Workbook

Sheet Intro
B1: Hey! This is a manual planner for tracking + determining class binds across classes. | D1: Links
A2: Setup | B2: To use this, go to File -> Make A Copy. Then go here to fill in your binds, and then to your class.
A3: Quick Setup | B3: 1. Import my Edit Mode string from Export Strings sheet. 2. Download my addon Keybinding, type /kb and paste in the spec string. 3. Download OPie, paste in my OPie Master Ring string and bind the strings. | D3: Mount/Autorun | E3: Having mount + autorun on mouse buttons means you can move effectively while eating, or just real quick with your mouse before you get up to grab a drink. I use Mouse 3, which is middle click.
B4: This version is the manual planner, but I've included my export strings. The import/export version lives here. Ideally, though, you want to use our keybind tool here. | E4: New tip! MogMount has a button in the WoW Keybinds that will use your assigned MogMount OR a random one. This helps keep the mount off your bar. I use this with an extra mouse button for handiness.
A5: Links | B5: Keybinding addon for profile imports/exports | D5: Modifiers | E5: Shift is easier for most, then Control and Alt are harder depending on keyboard & hand size, so prioritising them by ease is important. But if a button combo doesn't work, try another one.
B6: Keybinding webtool | D6: Strafing/Movement | E6: It might take some getting used to, but rebind A+D to Strafe Left + Strafe Right, then use Q+E for key abilities.
D7: Interface | E7: If adapting to a new key for interface elements doesn't work for you, try things like the Alt + the original key: i.e. Alt+V for nameplates, Alt+Z for sit and Alt+C for character pane!
D8: Macros | E8: There are tons of helpful macros here.
A9: Keybinding Principles | B9: Don't use keys you can't comfortably reach. | D9: OPie | E9: Try out OPie. It's another addon to rely on & set up, but it's worth it.
B10: Put abilities you press most often on the closest and easiest buttons. | D10: Mouse Buttons | E10: I use a Steelseries Aerox 9, which has 12 buttons on the side. However, this sheet accounts for every setup - so at least a 70% keyboard and a mouse with just 2 buttons - M4 and M5.
B11: Use your mouse buttons to instantly access emergency buttons.
B12: Make sure to plan your binds around your hand. Use your fingers for rotation abilities and thumb (or mouse buttons) for off-GCDs. | E12: Find this useful? Check out our Youtube channel and our website - we offer a lot more on both!
B13: Use modifiers (Shift, Ctrl, Alt) to get extra mileage out of the best keys.
B14: Bind a good Interact key to save tons of time. I use ` which is right beside the 1 key.
B15: Use mouseover casting instead of clicking unitframes.
B16: Organise your abilities in a way that makes sense to you.
B17: Use the same key for the same effect across classes: i.e. V always interrupts, X is always movement.
B18: Ensure you can move while pressing instant casts as a ranged DPS.
B19: Avoid binding off-GCDs and GCDs in ways you can't combo them.

Sheet Export Strings
A1: Spec | B1: V1 (Pre-EAB) | C1: Keybinding Addon String
A2: Blood | B2: MSxzcGVsbCwyMDY5MzAsc3BlbGwsMSx8MixzcGVsbCwxOTUxODIsc3BlbGwsMix8MyxzcGVsbCw1MDg0MixzcGVsbCwzLHw0LG1hY3JvLDQzMjY1LDQzMjY1LDQsLFJHVmhkR2dnWVc1a0lFUmxZMkY1SUNoSGNtOTFibVFwLEkzTm9iM2QwYjI5c2RHbHdJRVJsWVhSb0lHRnVaQ0JFWldOaGVRb3ZZMkZ6ZENCYlFHTjFjbk52Y2wwZ1JHVmhkR2dnWVc1a0lFUmxZMkY1Q2c9PSxjfDUsc3BlbGwsNDk5OTgsc3BlbGwsUSx8NixzcGVsbCw1NTIzMyxzcGVsbCxFLHw3LHNwZWxsLDE5NTI5MixzcGVsbCxSLHw4LHNwZWxsLDEyNjM4MjQsc3BlbGwsRix8OSM1LHwxMCM1LHwxMSM1LHwxMiM1LHwxMyM1LHwxNCM1LHwxNSM1LHwxNiM1LHwxNyM1LHwxOCM1LHwxOSM1LHwyMCM1LHwyMSM1LHwyMiM1LHwyMyM1LHwyNCM1LHwyNSM0LFNISUZULVosfDI2LHNwZWxsLDIxMjU1MixzcGVsbCxTSElGVC1YLHwyNyxzcGVsbCwyMDcxNjcsc3BlbGwsU0hJRlQtQyx8Mjgsc3BlbGwsNDU1MjQsc3BlbGwsU0hJRlQtVix8Mjksc3BlbGwsNDg3OTIsc3BlbGwsWix8MzAsc3BlbGwsNDgyNjUsc3BlbGwsWCx8MzEsc3BlbGwsMjIxNTYyLHNwZWxsLEMsfDMyLHNwZWxsLDQ3NTI4LHNwZWxsLFYsfDMzIzUsfDM0IzUsfDM1IzUsfDM2IzUsfDM3LHNwZWxsLDc3NjA2LHNwZWxsLEFMVC1aLHwzOCxzcGVsbCwyMDMxNzMsc3BlbGwsQUxULVgsQ1RSTC1CVVRUT040fDM5IzQsQUxULUMsQUxULUJVVFRPTjV8NDAsc3VtbW9ubW91bnQsNzIyODYsLEFMVC1WLEFMVC1CVVRUT040fDQxIzQsQ1RSTC1aLFNISUZULUJVVFRPTjV8NDIjNCxDVFJMLVgsU0hJRlQtQlVUVE9ONHw0MyxzcGVsbCw0ODcwNyxzcGVsbCxDVFJMLUMsQlVUVE9ONXw0NCxzcGVsbCw1NjIyMixzcGVsbCxCVVRUT040LENUUkwtVnw0NSM1LHw0NiM1LHw0NyM1LHw0OCM1LHw0OSM0LENUUkwtMSx8NTAsc3BlbGwsNDkwMzksc3BlbGwsQ1RSTC0yLHw1MSxzcGVsbCw0NzU0MSxzcGVsbCxDVFJMLTMsfDUyLHNwZWxsLDQ4NzQzLHNwZWxsLENUUkwtNCx8NTMsc3BlbGwsMTExNjczLHNwZWxsLENUUkwtUSx8NTQsc3BlbGwsMzcxNCxzcGVsbCxDVFJMLUUsfDU1LG1hY3JvLDUxMDUyLDUxMDUyLENUUkwtUiwsUVc1MGFTMU5ZV2RwWXlCYWIyNWxJQ2hIY205MWJtUXAsSTNOb2IzZDBiMjlzZEdsd0lFRnVkR2t0VFdGbmFXTWdXbTl1WlFvdlkyRnpkQ0JiUUdOMWNuTnZjbDBnUVc1MGFTMU5ZV2RwWXlCYWIyNWxDZz09LGN8NTYsc3BlbGwsNjE5OTksc3BlbGwsQ1RSTC1GLHw1NyM1LHw1OCM1LHw1OSM1LHw2MCM1LHw2MSxzcGVsbCw0OTAyOCxzcGVsbCxTSElGVC0xLHw2MixzcGVsbCw0Mzk4NDMsc3BlbGwsU0hJRlQtMix8NjMjNCxTSElGVC0zLHw2NCxzcGVsbCw0NjU4NSxzcGVsbCxTSElGVC00LHw2NSxzcGVsbCw0OTU3NixzcGVsbCxTSElGVC1RLHw2NixzcGVsbCwxMDgxOTksc3BlbGwsU0hJRlQtRSx8NjcjNCxTSElGVC1SLHw2OCM0LFNISUZULUYsfDY5IzUsfDcwIzUsfDcxIzUsfDcyIzUsfDczIzUsfDc0IzUsfDc1IzUsfDc2IzUsfDc3IzUsfDc4IzUsfDc5IzUsfDgwIzUsfDgxIzUsfDgyIzUsfDgzIzUsfDg0IzUsfDg1IzUsfDg2IzUsfDg3IzUsfDg4IzUsfDg5IzUsfDkwIzUsfDkxIzUsfDkyIzUsfDkzIzUsfDk0IzUsfDk1IzUsfDk2IzUsfDk3IzUsfDk4IzUsfDk5IzUsfDEwMCM1LHwxMDEjNSx8MTAyIzUsfDEwMyM1LHwxMDQjNSx8MTA1IzUsfDEwNiM1LHwxMDcjNSx8MTA4IzUsfDEwOSM1LHwxMTAjNSx8MTExIzUsfDExMiM1LHwxMTMjNSx8MTE0IzUsfDExNSM1LHwxMTYjNSx8MTE3IzUsfDExOCM1LHwxMTkjNSx8MTIwIzUsfDEyMSxzcGVsbCwzNzI2MDgsc3BlbGwsLHwxMjIsc3BlbGwsMzcyNjEwLHNwZWxsLCx8MTIzLHNwZWxsLDM2MTU4NCxzcGVsbCwsfDEyNCxzcGVsbCw0MjU3ODIsc3BlbGwsLHwxMjUsc3BlbGwsNDAzMDkyLHNwZWxsLCx8MTI2IzUsfDEyNyM1LHwxMjgjNSx8MTI5IzUsfDEzMCM1LHwxMzEjNSx8MTMyIzUsfDEzMyM1LHwxMzQjNSx8MTM1IzUsfDEzNiM1LHwxMzcjNSx8MTM4IzUsfDEzOSM1LHwxNDAjNSx8MTQxIzUsfDE0MiM1LHwxNDMjNSx8MTQ0IzUsfDE0NSxtYWNybywxMjMxNDExLDEyMzE0MTEsLCxSVzVvWVc1alpWRnZURWhsWVd4MGFFMWhZM0p2LEkzTm9iM2QwYjI5c2RHbHdDaTlqWVhOMElGdHViMk52YldKaGRGMGdVbVZqZFhCbGNtRjBaUW92WTJGemRITmxjWFZsYm1ObElGdGpiMjFpWVhSZElISmxjMlYwUFdOdmJXSmhkQ0JwZEdWdE9qSXhNVGczT1E9PSxhfDE0NixtYWNybywzIzQsUlc1b1lXNWpaVkZ2VEVSeWFXNXJUV0ZqY204PSxJM05vYjNkMGIyOXNkR2x3Q2c9PSxhfDE0NyxpdGVtLDIxMjI1OCwsLHwxNDgjNSx8MTQ5LG1hY3JvLDE0OCxpdGVtLCwsVkhKcGJtdGxkQ0F4LEkzTm9iM2QwYjI5c2RHbHdDaTkxYzJVZ1cwQmpkWEp6YjNKZE1UTUssYXwxNTAsc3BlbGwsNTk1NDUsc3BlbGwsLHwxNTEjNSx8MTUyIzUsfDE1MyM1LHwxNTQjNSx8MTU1IzUsfDE1NiM1LHwxNTcjNSx8MTU4IzUsfDE1OSM1LHwxNjAjNSx8MTYxIzUsfDE2MiM1LHwxNjMjNSx8MTY0IzUsfDE2NSM1LHwxNjYjNSx8MTY3IzUsfDE2OCM1LHwxNjkjNSx8MTcwIzUsfDE3MSM1LHwxNzIjNSx8MTczIzUsfDE3NCM1LHwxNzUjNSx8MTc2IzUsfDE3NyM1LHwxNzgjNSx8MTc5IzUsfDE4MCM1LA== | C2: MCxfaGVhZGVyLGRlYXRoa25pZ2h0LDI1MCwsfDEsc3BlbGwsMjA2OTMwLHNwZWxsLDEsfDIsc3BlbGwsMTk1MTgyLHNwZWxsLDIsfDMsc3BlbGwsNTA4NDIsc3BlbGwsMyx8NCxtYWNybyw0MzI2NSw0MzI2NSw0LCxSR1ZoZEdnZ1lXNWtJRVJsWTJGNUlDaEhjbTkxYm1RcCxJM05vYjNkMGIyOXNkR2x3SUVSbFlYUm9JR0Z1WkNCRVpXTmhlUW92WTJGemRDQmJRR04xY25OdmNsMGdSR1ZoZEdnZ1lXNWtJRVJsWTJGNUNnPT0sY3w1LHNwZWxsLDQ5OTk4LHNwZWxsLFEsfDYsc3BlbGwsNTUyMzMsc3BlbGwsRSx8NyxzcGVsbCwxOTUyOTIsc3BlbGwsUix8OCxzcGVsbCwxMjYzODI0LHNwZWxsLEYsfDkjNSx8MTAjNSx8MTEjNSx8MTIjNSx8MTMjNSx8MTQjNSx8MTUjNSx8MTYjNSx8MTcjNSx8MTgjNSx8MTkjNSx8MjAjNSx8MjEjNSx8MjIjNSx8MjMjNSx8MjQjNSx8MjUjNCxTSElGVC1aLHwyNixzcGVsbCwyMTI1NTIsc3BlbGwsU0hJRlQtWCx8Mjcsc3BlbGwsMjA3MTY3LHNwZWxsLFNISUZULUMsfDI4LHNwZWxsLDQ1NTI0LHNwZWxsLFNISUZULVYsfDI5LHNwZWxsLDQ4NzkyLHNwZWxsLFosfDMwLHNwZWxsLDQ4MjY1LHNwZWxsLFgsfDMxLHNwZWxsLDIyMTU2MixzcGVsbCxDLHwzMixzcGVsbCw0NzUyOCxzcGVsbCxWLHwzMyM1LHwzNCM1LHwzNSM1LHwzNiM1LHwzNyxzcGVsbCw3NzYwNixzcGVsbCxBTFQtWixDVFJMLUJVVFRPTjV8Mzgsc3BlbGwsMjAzMTczLHNwZWxsLEFMVC1YLENUUkwtQlVUVE9ONHwzOSM0LEFMVC1DLEFMVC1CVVRUT041fDQwLHN1bW1vbm1vdW50LDcyMjg2LCxBTFQtVixBTFQtQlVUVE9ONHw0MSM0LENUUkwtWixTSElGVC1CVVRUT041fDQyIzQsQ1RSTC1YLFNISUZULUJVVFRPTjR8NDMsc3BlbGwsNDg3MDcsc3BlbGwsQ1RSTC1DLEJVVFRPTjV8NDQsc3BlbGwsNTYyMjIsc3BlbGwsQlVUVE9ONCxDVFJMLVZ8NDUjNSx8NDYjNSx8NDcjNSx8NDgjNSx8NDkjNCxDVFJMLTEsfDUwLHNwZWxsLDQ5MDM5LHNwZWxsLENUUkwtMix8NTEsc3BlbGwsNDc1NDEsc3BlbGwsQ1RSTC0zLHw1MixzcGVsbCw0ODc0MyxzcGVsbCxDVFJMLTQsfDUzLHNwZWxsLDExMTY3MyxzcGVsbCxDVFJMLVEsfDU0LHNwZWxsLDM3MTQsc3BlbGwsQ1RSTC1FLHw1NSxtYWNybyw1MTA1Miw1MTA1MixDVFJMLVIsLFFXNTBhUzFOWVdkcFl5QmFiMjVsSUNoSGNtOTFibVFwLEkzTm9iM2QwYjI5c2RHbHdJRUZ1ZEdrdFRXRm5hV01nV205dVpRb3ZZMkZ6ZENCYlFHTjFjbk52Y2wwZ1FXNTBhUzFOWVdkcFl5QmFiMjVsQ2c9PSxjfDU2LHNwZWxsLDYxOTk5LHNwZWxsLENUUkwtRix8NTcjNSx8NTgjNSx8NTkjNSx8NjAjNSx8NjEsc3BlbGwsNDkwMjgsc3BlbGwsU0hJRlQtMSx8NjIsc3BlbGwsNDM5ODQzLHNwZWxsLFNISUZULTIsfDYzIzQsU0hJRlQtMyx8NjQsc3BlbGwsNDY1ODUsc3BlbGwsU0hJRlQtNCx8NjUsc3BlbGwsNDk1NzYsc3BlbGwsU0hJRlQtUSx8NjYsc3BlbGwsMTA4MTk5LHNwZWxsLFNISUZULUUsfDY3IzQsU0hJRlQtUix8NjgjNCxTSElGVC1GLHw2OSM1LHw3MCM1LHw3MSM1LHw3MiM1LHw3MyM1LHw3NCM1LHw3NSM1LHw3NiM1LHw3NyM1LHw3OCM1LHw3OSM1LHw4MCM1LHw4MSM1LHw4MiM1LHw4MyM1LHw4NCM1LHw4NSM1LHw4NiM1LHw4NyM1LHw4OCM1LHw4OSM1LHw5MCM1LHw5MSM1LHw5MiM1LHw5MyM1LHw5NCM1LHw5NSM1LHw5NiM1LHw5NyM1LHw5OCM1LHw5OSM1LHwxMDAjNSx8MTAxIzUsfDEwMiM1LHwxMDMjNSx8MTA0IzUsfDEwNSM1LHwxMDYjNSx8MTA3IzUsfDEwOCM1LHwxMDkjNSx8MTEwIzUsfDExMSM1LHwxMTIjNSx8MTEzIzUsfDExNCM1LHwxMTUjNSx8MTE2IzUsfDExNyM1LHwxMTgjNSx8MTE5IzUsfDEyMCM1LHwxMjEsc3BlbGwsMzcyNjA4LHNwZWxsLCx8MTIyLHNwZWxsLDM3MjYxMCxzcGVsbCwsfDEyMyxzcGVsbCwzNjE1ODQsc3BlbGwsLHwxMjQsc3BlbGwsNDI1NzgyLHNwZWxsLCx8MTI1LHNwZWxsLDQwMzA5MixzcGVsbCwsfDEyNiM1LHwxMjcjNSx8MTI4IzUsfDEyOSM1LHwxMzAjNSx8MTMxIzUsfDEzMiM1LHwxMzMjNSx8MTM0IzUsfDEzNSM1LHwxMzYjNSx8MTM3IzUsfDEzOCM1LHwxMzkjNSx8MTQwIzUsfDE0MSM1LHwxNDIjNSx8MTQzIzUsfDE0NCM1LHwxNDUsbWFjcm8sMTIzMTQxMSwxMjMxNDExLCwsUlc1b1lXNWpaVkZ2VEVobFlXeDBhRTFoWTNKdixJM05vYjNkMGIyOXNkR2x3Q2k5allYTjBJRnR1YjJOdmJXSmhkRjBnVW1WamRYQmxjbUYwWlFvdlkyRnpkSE5sY1hWbGJtTmxJRnRqYjIxaVlYUmRJSEpsYzJWMFBXTnZiV0poZENCcGRHVnRPakl4TVRnM09RPT0sYXwxNDYsbWFjcm8sMTQ1LGl0ZW0sLCxSVzVvWVc1alpWRnZURVJ5YVc1clRXRmpjbTg9LEkzTm9iM2QwYjI5c2RHbHdDaTlqWVhOMGMyVnhkV1Z1WTJVZ2NtVnpaWFE5WTI5dFltRjBJR2wwWlcwNk1UY3lNRFl6Q2c9PSxhfDE0NyxtYWNybywxNDYsaXRlbSwsLFJHRnRZV2RsSUZCdmRBPT0sSTNOb2IzZDBiMjlzZEdsd0NpOTFjMlVnYVhSbGJUb3lOREV6TURnSyxhfDE0OCxtYWNybywxMSM0LFVHeGhZMlZvYjJ4a1pYST0sVUd4aFkyVm9iMnhrWlhJZ2JXRmpjbThnWm05eUlHbDBaVzF6SUd4cGEyVWdibWwwY204Z1ltOXZjM1FnYjNJZ2MyeHZkeUJtWVd4c0lHTnNiMkZyTGdvPSxhfDE0OSxtYWNybywxNDgsaXRlbSwsLFZISnBibXRsZENBeCxJM05vYjNkMGIyOXNkR2x3Q2k5MWMyVWdXMEJqZFhKemIzSmRNVE1LLGF8MTUwLHNwZWxsLDU5NTQ1LHNwZWxsLCx8MTUxIzUsfDE1MiM1LHwxNTMjNSx8MTU0IzUsfDE1NSM1LHwxNTYjNSx8MTU3IzUsfDE1OCM1LHwxNTkjNSx8MTYwIzUsfDE2MSM1LHwxNjIjNSx8MTYzIzUsfDE2NCM1LHwxNjUjNSx8MTY2IzUsfDE2NyM1LHwxNjgjNSx8MTY5IzUsfDE3MCM1LHwxNzEjNSx8MTcyIzUsfDE3MyM1LHwxNzQjNSx8MTc1IzUsfDE3NiM1LHwxNzcjNSx8MTc4IzUsfDE3OSM1LHwxODAjNSx8MTgxIzQsNSx8MTgyIzQsYCx8MTgzIzQsRjEsfDE4NCM0LEYyLHwxODUjNCxGMyx8MTg2IzQsRjQsfDE4NyM1LHwxODgjNSx8MTg5IzUsfDE5MCM1LHwxOTEjNSx8MTkyIzUs
A3: Frost | B3: MSxzcGVsbCw0OTAyMCxzcGVsbCwxLHwyLHNwZWxsLDQ5MTQzLHNwZWxsLDIsfDMsc3BlbGwsNDkxODQsc3BlbGwsMyx8NCxzcGVsbCwyMDcyMzAsc3BlbGwsNCx8NSxzcGVsbCw1MTI3MSxzcGVsbCxRLHw2LHNwZWxsLDE5NDkxMyxzcGVsbCxFLHw3LHNwZWxsLDQ3NTY4LHNwZWxsLFIsfDgsc3BlbGwsMjc5MzAyLHNwZWxsLEYsfDkjNSx8MTAjNSx8MTEjNSx8MTIjNSx8MTMjNSx8MTQjNSx8MTUjNSx8MTYjNSx8MTcjNSx8MTgjNSx8MTkjNSx8MjAjNSx8MjEjNSx8MjIjNSx8MjMjNSx8MjQjNSx8MjUjNCxTSElGVC1aLHwyNixzcGVsbCwyMTI1NTIsc3BlbGwsU0hJRlQtWCx8Mjcsc3BlbGwsMjA3MTY3LHNwZWxsLFNISUZULUMsfDI4LHNwZWxsLDQ1NTI0LHNwZWxsLFNISUZULVYsfDI5LHNwZWxsLDQ4NzkyLHNwZWxsLFosfDMwLHNwZWxsLDQ4MjY1LHNwZWxsLFgsfDMxLHNwZWxsLDIyMTU2MixzcGVsbCxDLHwzMixzcGVsbCw0NzUyOCxzcGVsbCxWLHwzMyM1LHwzNCM1LHwzNSM1LHwzNiM1LHwzNyxzcGVsbCw3NzYwNixzcGVsbCxBTFQtWix8MzgjNCxBTFQtWCxDVFJMLUJVVFRPTjR8MzkjNCxBTFQtQyxBTFQtQlVUVE9ONXw0MCxzdW1tb25tb3VudCw3MjI4NiwsQUxULVYsQUxULUJVVFRPTjR8NDEjNCxDVFJMLVosU0hJRlQtQlVUVE9ONXw0MiM0LENUUkwtWCxTSElGVC1CVVRUT040fDQzLHNwZWxsLDQ4NzA3LHNwZWxsLENUUkwtQyxCVVRUT041fDQ0LHNwZWxsLDU2MjIyLHNwZWxsLEJVVFRPTjQsQ1RSTC1WfDQ1IzUsfDQ2IzUsfDQ3IzUsfDQ4IzUsfDQ5LHNwZWxsLDQ5OTk4LHNwZWxsLENUUkwtMSx8NTAsc3BlbGwsNDkwMzksc3BlbGwsQ1RSTC0yLHw1MSxzcGVsbCw0NzU0MSxzcGVsbCxDVFJMLTMsfDUyLHNwZWxsLDQ4NzQzLHNwZWxsLENUUkwtNCx8NTMsc3BlbGwsMTExNjczLHNwZWxsLENUUkwtUSx8NTQsc3BlbGwsMzcxNCxzcGVsbCxDVFJMLUUsfDU1LG1hY3JvLDUxMDUyLDUxMDUyLENUUkwtUiwsUVc1MGFTMU5ZV2RwWXlCYWIyNWxJQ2hIY205MWJtUXAsSTNOb2IzZDBiMjlzZEdsd0lFRnVkR2t0VFdGbmFXTWdXbTl1WlFvdlkyRnpkQ0JiUUdOMWNuTnZjbDBnUVc1MGFTMU5ZV2RwWXlCYWIyNWxDZz09LGN8NTYsc3BlbGwsNjE5OTksc3BlbGwsQ1RSTC1GLHw1NyM1LHw1OCM1LHw1OSM1LHw2MCM1LHw2MSxzcGVsbCwxMjQ5NjU4LHNwZWxsLFNISUZULTEsfDYyLHNwZWxsLDQzOTg0MyxzcGVsbCxTSElGVC0yLHw2MyxzcGVsbCwxOTY3NzAsc3BlbGwsU0hJRlQtMyx8NjQsc3BlbGwsNDY1ODUsc3BlbGwsU0hJRlQtNCx8NjUsc3BlbGwsNDk1NzYsc3BlbGwsU0hJRlQtUSx8NjYsbWFjcm8sNDMyNjUsNDMyNjUsU0hJRlQtRSwsUkdWaGRHZ2dZVzVrSUVSbFkyRjVJQ2hIY205MWJtUXAsSTNOb2IzZDBiMjlzZEdsd0lFUmxZWFJvSUdGdVpDQkVaV05oZVFvdlkyRnpkQ0JiUUdOMWNuTnZjbDBnUkdWaGRHZ2dZVzVrSUVSbFkyRjVDZz09LGN8NjcjNCxTSElGVC1SLHw2OCM0LFNISUZULUYsfDY5IzUsfDcwIzUsfDcxIzUsfDcyIzUsfDczIzUsfDc0IzUsfDc1IzUsfDc2IzUsfDc3IzUsfDc4IzUsfDc5IzUsfDgwIzUsfDgxIzUsfDgyIzUsfDgzIzUsfDg0IzUsfDg1IzUsfDg2IzUsfDg3IzUsfDg4IzUsfDg5IzUsfDkwIzUsfDkxIzUsfDkyIzUsfDkzIzUsfDk0IzUsfDk1IzUsfDk2IzUsfDk3IzUsfDk4IzUsfDk5IzUsfDEwMCM1LHwxMDEjNSx8MTAyIzUsfDEwMyM1LHwxMDQjNSx8MTA1IzUsfDEwNiM1LHwxMDcjNSx8MTA4IzUsfDEwOSM1LHwxMTAjNSx8MTExIzUsfDExMiM1LHwxMTMjNSx8MTE0IzUsfDExNSM1LHwxMTYjNSx8MTE3IzUsfDExOCM1LHwxMTkjNSx8MTIwIzUsfDEyMSxzcGVsbCwzNzI2MDgsc3BlbGwsLHwxMjIsc3BlbGwsMzcyNjEwLHNwZWxsLCx8MTIzLHNwZWxsLDM2MTU4NCxzcGVsbCwsfDEyNCxzcGVsbCw0MjU3ODIsc3BlbGwsLHwxMjUsc3BlbGwsNDAzMDkyLHNwZWxsLCx8MTI2IzUsfDEyNyM1LHwxMjgjNSx8MTI5IzUsfDEzMCM1LHwxMzEjNSx8MTMyIzUsfDEzMyM1LHwxMzQjNSx8MTM1IzUsfDEzNiM1LHwxMzcjNSx8MTM4IzUsfDEzOSM1LHwxNDAjNSx8MTQxIzUsfDE0MiM1LHwxNDMjNSx8MTQ0IzUsfDE0NSxtYWNybywxMjMxNDExLDEyMzE0MTEsLCxSVzVvWVc1alpWRnZURWhsWVd4MGFFMWhZM0p2LEkzTm9iM2QwYjI5c2RHbHdDaTlqWVhOMElGdHViMk52YldKaGRGMGdVbVZqZFhCbGNtRjBaUW92WTJGemRITmxjWFZsYm1ObElGdGpiMjFpWVhSZElISmxjMlYwUFdOdmJXSmhkQ0JwZEdWdE9qSXhNVGczT1E9PSxhfDE0NixtYWNybyw0IzQsUlc1b1lXNWpaVkZ2VEVSeWFXNXJUV0ZqY204PSxJM05vYjNkMGIyOXNkR2x3Q2c9PSxhfDE0NyxtYWNybywxNDYsaXRlbSwsLFJHRnRZV2RsSUZCdmRBPT0sSTNOb2IzZDBiMjlzZEdsd0NpOTFjMlVnYVhSbGJUb3lOREV6TURnPSxhfDE0OCxtYWNybywxMSM0LFVHeGhZMlZvYjJ4a1pYST0sVUd4aFkyVm9iMnhrWlhJZ2JXRmpjbThnWm05eUlHbDBaVzF6SUd4cGEyVWdibWwwY204Z1ltOXZjM1FnYjNJZ2MyeHZkeUJtWVd4c0lHTnNiMkZyTGc9PSxhfDE0OSxtYWNybywxNDgsaXRlbSwsLFZISnBibXRsZENBeCxJM05vYjNkMGIyOXNkR2x3Q2k5MWMyVWdXMEJqZFhKemIzSmRNVE1LLGF8MTUwLHNwZWxsLDU5NTQ1LHNwZWxsLCx8MTUxIzUsfDE1MiM1LHwxNTMjNSx8MTU0IzUsfDE1NSM1LHwxNTYjNSx8MTU3IzUsfDE1OCM1LHwxNTkjNSx8MTYwIzUsfDE2MSM1LHwxNjIjNSx8MTYzIzUsfDE2NCM1LHwxNjUjNSx8MTY2IzUsfDE2NyM1LHwxNjgjNSx8MTY5IzUsfDE3MCM1LHwxNzEjNSx8MTcyIzUsfDE3MyM1LHwxNzQjNSx8MTc1IzUsfDE3NiM1LHwxNzcjNSx8MTc4IzUsfDE3OSM1LHwxODAjNSw= | C3: MCxfaGVhZGVyLGRlYXRoa25pZ2h0LDI1MSwsfDEsc3BlbGwsNDkwMjAsc3BlbGwsMSx8MixzcGVsbCw0OTE0MyxzcGVsbCwyLHwzLHNwZWxsLDQ5MTg0LHNwZWxsLDMsfDQsc3BlbGwsMjA3MjMwLHNwZWxsLDQsfDUsc3BlbGwsNTEyNzEsc3BlbGwsUSx8NixzcGVsbCwxOTQ5MTMsc3BlbGwsRSx8NyxzcGVsbCw0NzU2OCxzcGVsbCxSLHw4LHNwZWxsLDI3OTMwMixzcGVsbCxGLHw5IzUsfDEwIzUsfDExIzUsfDEyIzUsfDEzIzUsfDE0IzUsfDE1IzUsfDE2IzUsfDE3IzUsfDE4IzUsfDE5IzUsfDIwIzUsfDIxIzUsfDIyIzUsfDIzIzUsfDI0IzUsfDI1IzQsU0hJRlQtWix8MjYsc3BlbGwsMjEyNTUyLHNwZWxsLFNISUZULVgsfDI3LHNwZWxsLDIwNzE2NyxzcGVsbCxTSElGVC1DLHwyOCxzcGVsbCw0NTUyNCxzcGVsbCxTSElGVC1WLHwyOSxzcGVsbCw0ODc5MixzcGVsbCxaLHwzMCxzcGVsbCw0ODI2NSxzcGVsbCxYLHwzMSxzcGVsbCwyMjE1NjIsc3BlbGwsQyx8MzIsc3BlbGwsNDc1Mjgsc3BlbGwsVix8MzMjNSx8MzQjNSx8MzUjNSx8MzYjNSx8Mzcsc3BlbGwsNzc2MDYsc3BlbGwsQUxULVosQ1RSTC1CVVRUT041fDM4IzQsQUxULVgsQ1RSTC1CVVRUT040fDM5IzQsQUxULUMsQUxULUJVVFRPTjV8NDAsc3VtbW9ubW91bnQsNzIyODYsLEFMVC1WLEFMVC1CVVRUT040fDQxIzQsQ1RSTC1aLFNISUZULUJVVFRPTjV8NDIjNCxDVFJMLVgsU0hJRlQtQlVUVE9ONHw0MyxzcGVsbCw0ODcwNyxzcGVsbCxDVFJMLUMsQlVUVE9ONXw0NCxzcGVsbCw1NjIyMixzcGVsbCxCVVRUT040LENUUkwtVnw0NSM1LHw0NiM1LHw0NyM1LHw0OCM1LHw0OSxzcGVsbCw0OTk5OCxzcGVsbCxDVFJMLTEsfDUwLHNwZWxsLDQ5MDM5LHNwZWxsLENUUkwtMix8NTEsc3BlbGwsNDc1NDEsc3BlbGwsQ1RSTC0zLHw1MixzcGVsbCw0ODc0MyxzcGVsbCxDVFJMLTQsfDUzLHNwZWxsLDExMTY3MyxzcGVsbCxDVFJMLVEsfDU0LHNwZWxsLDM3MTQsc3BlbGwsQ1RSTC1FLHw1NSxtYWNybyw1MTA1Miw1MTA1MixDVFJMLVIsLFFXNTBhUzFOWVdkcFl5QmFiMjVsSUNoSGNtOTFibVFwLEkzTm9iM2QwYjI5c2RHbHdJRUZ1ZEdrdFRXRm5hV01nV205dVpRb3ZZMkZ6ZENCYlFHTjFjbk52Y2wwZ1FXNTBhUzFOWVdkcFl5QmFiMjVsQ2c9PSxjfDU2LHNwZWxsLDYxOTk5LHNwZWxsLENUUkwtRix8NTcjNSx8NTgjNSx8NTkjNSx8NjAjNSx8NjEsc3BlbGwsMTI0OTY1OCxzcGVsbCxTSElGVC0xLHw2MixzcGVsbCw0Mzk4NDMsc3BlbGwsU0hJRlQtMix8NjMsc3BlbGwsMTk2NzcwLHNwZWxsLFNISUZULTMsfDY0LHNwZWxsLDQ2NTg1LHNwZWxsLFNISUZULTQsfDY1LHNwZWxsLDQ5NTc2LHNwZWxsLFNISUZULVEsfDY2LG1hY3JvLDQzMjY1LDQzMjY1LFNISUZULUUsLFJHVmhkR2dnWVc1a0lFUmxZMkY1SUNoSGNtOTFibVFwLEkzTm9iM2QwYjI5c2RHbHdJRVJsWVhSb0lHRnVaQ0JFWldOaGVRb3ZZMkZ6ZENCYlFHTjFjbk52Y2wwZ1JHVmhkR2dnWVc1a0lFUmxZMkY1Q2c9PSxjfDY3IzQsU0hJRlQtUix8NjgjNCxTSElGVC1GLHw2OSM1LHw3MCM1LHw3MSM1LHw3MiM1LHw3MyM1LHw3NCM1LHw3NSM1LHw3NiM1LHw3NyM1LHw3OCM1LHw3OSM1LHw4MCM1LHw4MSM1LHw4MiM1LHw4MyM1LHw4NCM1LHw4NSM1LHw4NiM1LHw4NyM1LHw4OCM1LHw4OSM1LHw5MCM1LHw5MSM1LHw5MiM1LHw5MyM1LHw5NCM1LHw5NSM1LHw5NiM1LHw5NyM1LHw5OCM1LHw5OSM1LHwxMDAjNSx8MTAxIzUsfDEwMiM1LHwxMDMjNSx8MTA0IzUsfDEwNSM1LHwxMDYjNSx8MTA3IzUsfDEwOCM1LHwxMDkjNSx8MTEwIzUsfDExMSM1LHwxMTIjNSx8MTEzIzUsfDExNCM1LHwxMTUjNSx8MTE2IzUsfDExNyM1LHwxMTgjNSx8MTE5IzUsfDEyMCM1LHwxMjEsc3BlbGwsMzcyNjA4LHNwZWxsLCx8MTIyLHNwZWxsLDM3MjYxMCxzcGVsbCwsfDEyMyxzcGVsbCwzNjE1ODQsc3BlbGwsLHwxMjQsc3BlbGwsNDI1NzgyLHNwZWxsLCx8MTI1LHNwZWxsLDQwMzA5MixzcGVsbCwsfDEyNiM1LHwxMjcjNSx8MTI4IzUsfDEyOSM1LHwxMzAjNSx8MTMxIzUsfDEzMiM1LHwxMzMjNSx8MTM0IzUsfDEzNSM1LHwxMzYjNSx8MTM3IzUsfDEzOCM1LHwxMzkjNSx8MTQwIzUsfDE0MSM1LHwxNDIjNSx8MTQzIzUsfDE0NCM1LHwxNDUsbWFjcm8sMTIzMTQxMSwxMjMxNDExLCwsUlc1b1lXNWpaVkZ2VEVobFlXeDBhRTFoWTNKdixJM05vYjNkMGIyOXNkR2x3Q2k5allYTjBJRnR1YjJOdmJXSmhkRjBnVW1WamRYQmxjbUYwWlFvdlkyRnpkSE5sY1hWbGJtTmxJRnRqYjIxaVlYUmRJSEpsYzJWMFBXTnZiV0poZENCcGRHVnRPakl4TVRnM09RPT0sYXwxNDYsbWFjcm8sMTQ1LGl0ZW0sLCxSVzVvWVc1alpWRnZURVJ5YVc1clRXRmpjbTg9LEkzTm9iM2QwYjI5c2RHbHdDaTlqWVhOMGMyVnhkV1Z1WTJVZ2NtVnpaWFE5WTI5dFltRjBJR2wwWlcwNk1UY3lNRFl6Q2c9PSxhfDE0NyxtYWNybywxNDYsaXRlbSwsLFJHRnRZV2RsSUZCdmRBPT0sSTNOb2IzZDBiMjlzZEdsd0NpOTFjMlVnYVhSbGJUb3lOREV6TURnSyxhfDE0OCxtYWNybywxMSM0LFVHeGhZMlZvYjJ4a1pYST0sVUd4aFkyVm9iMnhrWlhJZ2JXRmpjbThnWm05eUlHbDBaVzF6SUd4cGEyVWdibWwwY204Z1ltOXZjM1FnYjNJZ2MyeHZkeUJtWVd4c0lHTnNiMkZyTGdvPSxhfDE0OSxtYWNybywxNDgsaXRlbSwsLFZISnBibXRsZENBeCxJM05vYjNkMGIyOXNkR2x3Q2k5MWMyVWdXMEJqZFhKemIzSmRNVE1LLGF8MTUwLHNwZWxsLDU5NTQ1LHNwZWxsLCx8MTUxIzUsfDE1MiM1LHwxNTMjNSx8MTU0IzUsfDE1NSM1LHwxNTYjNSx8MTU3IzUsfDE1OCM1LHwxNTkjNSx8MTYwIzUsfDE2MSM1LHwxNjIjNSx8MTYzIzUsfDE2NCM1LHwxNjUjNSx8MTY2IzUsfDE2NyM1LHwxNjgjNSx8MTY5IzUsfDE3MCM1LHwxNzEjNSx8MTcyIzUsfDE3MyM1LHwxNzQjNSx8MTc1IzUsfDE3NiM1LHwxNzcjNSx8MTc4IzUsfDE3OSM1LHwxODAjNSx8MTgxIzQsNSx8MTgyIzQsYCx8MTgzIzQsRjEsfDE4NCM0LEYyLHwxODUjNCxGMyx8MTg2IzQsRjQsfDE4NyM1LHwxODgjNSx8MTg5IzUsfDE5MCM1LHwxOTEjNSx8MTkyIzUs
A4: Unholy | B4: MSxzcGVsbCw1NTA5MCxzcGVsbCwxLHwyLHNwZWxsLDg1OTQ4LHNwZWxsLDIsfDMsc3BlbGwsNDc1NDEsc3BlbGwsMyx8NCxzcGVsbCw0MzI2NSxzcGVsbCw0LHw1LHNwZWxsLDEyMzM0NDgsc3BlbGwsUSx8NixzcGVsbCwyMDczMTcsc3BlbGwsRSx8NyxzcGVsbCw3NzU3NSxzcGVsbCxSLHw4LHNwZWxsLDEyNDczNzgsc3BlbGwsRix8OSM1LHwxMCM1LHwxMSM1LHwxMiM1LHwxMyM1LHwxNCM1LHwxNSM1LHwxNiM1LHwxNyM1LHwxOCM1LHwxOSM1LHwyMCM1LHwyMSM1LHwyMiM1LHwyMyM1LHwyNCM1LHwyNSM0LFNISUZULVosfDI2LHNwZWxsLDIxMjU1MixzcGVsbCxTSElGVC1YLHwyNyxzcGVsbCwyMDcxNjcsc3BlbGwsU0hJRlQtQyx8Mjgsc3BlbGwsNDU1MjQsc3BlbGwsU0hJRlQtVix8Mjksc3BlbGwsNDg3OTIsc3BlbGwsWix8MzAsc3BlbGwsNDQ0MzQ3LHNwZWxsLFgsfDMxLHNwZWxsLDIyMTU2MixzcGVsbCxDLHwzMixzcGVsbCw0NzUyOCxzcGVsbCxWLHwzMyM1LHwzNCM1LHwzNSM1LHwzNiM1LHwzNyxzcGVsbCw3NzYwNixzcGVsbCxBTFQtWix8Mzgsc3BlbGwsMjEwMTI4LHNwZWxsLEFMVC1YLENUUkwtQlVUVE9ONHwzOSM0LEFMVC1DLEFMVC1CVVRUT041fDQwLHN1bW1vbm1vdW50LDcyMjg2LCxBTFQtVixBTFQtQlVUVE9ONHw0MSM0LENUUkwtWixTSElGVC1CVVRUT041fDQyIzQsQ1RSTC1YLFNISUZULUJVVFRPTjR8NDMsc3BlbGwsNDg3MDcsc3BlbGwsQ1RSTC1DLEJVVFRPTjV8NDQsc3BlbGwsNTYyMjIsc3BlbGwsQlVUVE9ONCxDVFJMLVZ8NDUjNSx8NDYjNSx8NDcjNSx8NDgjNSx8NDksc3BlbGwsNDk5OTgsc3BlbGwsQ1RSTC0xLHw1MCxzcGVsbCw0OTAzOSxzcGVsbCxDVFJMLTIsfDUxIzQsQ1RSTC0zLHw1MixzcGVsbCw0ODc0MyxzcGVsbCxDVFJMLTQsfDUzLHNwZWxsLDExMTY3MyxzcGVsbCxDVFJMLVEsfDU0LHNwZWxsLDM3MTQsc3BlbGwsQ1RSTC1FLHw1NSM0LENUUkwtUix8NTYsc3BlbGwsNjE5OTksc3BlbGwsQ1RSTC1GLHw1NyM1LHw1OCM1LHw1OSM1LHw2MCM1LHw2MSxzcGVsbCw0MjY1MCxzcGVsbCxTSElGVC0xLHw2MixzcGVsbCwzNDMyOTQsc3BlbGwsU0hJRlQtMix8NjMjNCxTSElGVC0zLHw2NCxzcGVsbCw0NjU4NCxzcGVsbCxTSElGVC00LHw2NSxzcGVsbCw0OTU3NixzcGVsbCxTSElGVC1RLHw2NiM0LFNISUZULUUsfDY3LHNwZWxsLDUxMDUyLHNwZWxsLFNISUZULVIsfDY4IzQsU0hJRlQtRix8NjkjNSx8NzAjNSx8NzEjNSx8NzIjNSx8NzMjNSx8NzQjNSx8NzUjNSx8NzYjNSx8NzcjNSx8NzgjNSx8NzkjNSx8ODAjNSx8ODEjNSx8ODIjNSx8ODMjNSx8ODQjNSx8ODUjNSx8ODYjNSx8ODcjNSx8ODgjNSx8ODkjNSx8OTAjNSx8OTEjNSx8OTIjNSx8OTMjNSx8OTQjNSx8OTUjNSx8OTYjNSx8OTcjNSx8OTgjNSx8OTkjNSx8MTAwIzUsfDEwMSM1LHwxMDIjNSx8MTAzIzUsfDEwNCM1LHwxMDUjNSx8MTA2IzUsfDEwNyM1LHwxMDgjNSx8MTA5IzUsfDExMCM1LHwxMTEjNSx8MTEyIzUsfDExMyM1LHwxMTQjNSx8MTE1IzUsfDExNiM1LHwxMTcjNSx8MTE4IzUsfDExOSM1LHwxMjAjNSx8MTIxLHNwZWxsLDM3MjYwOCxzcGVsbCwsfDEyMixzcGVsbCwzNzI2MTAsc3BlbGwsLHwxMjMsc3BlbGwsMzYxNTg0LHNwZWxsLCx8MTI0LHNwZWxsLDQwMzA5MixzcGVsbCwsfDEyNSxzcGVsbCw0MjU3ODIsc3BlbGwsLHwxMjYjNSx8MTI3IzUsfDEyOCM1LHwxMjkjNSx8MTMwIzUsfDEzMSM1LHwxMzIjNSx8MTMzIzUsfDEzNCM1LHwxMzUjNSx8MTM2IzUsfDEzNyM1LHwxMzgjNSx8MTM5IzUsfDE0MCM1LHwxNDEjNSx8MTQyIzUsfDE0MyM1LHwxNDQjNSx8MTQ1LG1hY3JvLDQjNCxSVzVvWVc1alpWRnZURVJ5YVc1clRXRmpjbTg9LEkzTm9iM2QwYjI5c2RHbHdDZz09LGF8MTQ2LG1hY3JvLDQjNCxSVzVvWVc1alpWRnZURVJ5YVc1clRXRmpjbTg9LEkzTm9iM2QwYjI5c2RHbHdDZz09LGF8MTQ3LG1hY3JvLDE0NixpdGVtLCwsUkdGdFlXZGxJRkJ2ZEE9PSxJM05vYjNkMGIyOXNkR2x3Q2k5MWMyVWdhWFJsYlRveU5ERXpNRGc9LGF8MTQ4LG1hY3JvLDExIzQsVUd4aFkyVm9iMnhrWlhJPSxVR3hoWTJWb2IyeGtaWElnYldGamNtOGdabTl5SUdsMFpXMXpJR3hwYTJVZ2JtbDBjbThnWW05dmMzUWdiM0lnYzJ4dmR5Qm1ZV3hzSUdOc2IyRnJMZz09LGF8MTQ5LG1hY3JvLDE0OCxpdGVtLCwsVkhKcGJtdGxkQ0F4LEkzTm9iM2QwYjI5c2RHbHdDaTkxYzJVZ1cwQmpkWEp6YjNKZE1UTUssYXwxNTAsc3BlbGwsNTk1NDUsc3BlbGwsLHwxNTEjNSx8MTUyIzUsfDE1MyM1LHwxNTQjNSx8MTU1IzUsfDE1NiM1LHwxNTcjNSx8MTU4IzUsfDE1OSM1LHwxNjAjNSx8MTYxIzUsfDE2MiM1LHwxNjMjNSx8MTY0IzUsfDE2NSM1LHwxNjYjNSx8MTY3IzUsfDE2OCM1LHwxNjkjNSx8MTcwIzUsfDE3MSM1LHwxNzIjNSx8MTczIzUsfDE3NCM1LHwxNzUjNSx8MTc2IzUsfDE3NyM1LHwxNzgjNSx8MTc5IzUsfDE4MCM1LA== | C4: MCxfaGVhZGVyLGRlYXRoa25pZ2h0LDI1MiwsfDEsc3BlbGwsNTUwOTAsc3BlbGwsMSx8MixzcGVsbCw4NTk0OCxzcGVsbCwyLHwzLHNwZWxsLDQ3NTQxLHNwZWxsLDMsfDQsc3BlbGwsNDMyNjUsc3BlbGwsNCx8NSxzcGVsbCwxMjMzNDQ4LHNwZWxsLFEsfDYsc3BlbGwsMjA3MzE3LHNwZWxsLEUsfDcsc3BlbGwsNzc1NzUsc3BlbGwsUix8OCxzcGVsbCwxMjQ3Mzc4LHNwZWxsLEYsfDkjNSx8MTAjNSx8MTEjNSx8MTIjNSx8MTMjNSx8MTQjNSx8MTUjNSx8MTYjNSx8MTcjNSx8MTgjNSx8MTkjNSx8MjAjNSx8MjEjNSx8MjIjNSx8MjMjNSx8MjQjNSx8MjUjNCxTSElGVC1aLHwyNixzcGVsbCwyMTI1NTIsc3BlbGwsU0hJRlQtWCx8Mjcsc3BlbGwsMjA3MTY3LHNwZWxsLFNISUZULUMsfDI4LHNwZWxsLDQ1NTI0LHNwZWxsLFNISUZULVYsfDI5LHNwZWxsLDQ4NzkyLHNwZWxsLFosfDMwLHNwZWxsLDQ0NDM0NyxzcGVsbCxYLHwzMSxzcGVsbCwyMjE1NjIsc3BlbGwsQyx8MzIsc3BlbGwsNDc1Mjgsc3BlbGwsVix8MzMjNSx8MzQjNSx8MzUjNSx8MzYjNSx8Mzcsc3BlbGwsNzc2MDYsc3BlbGwsQUxULVosQ1RSTC1CVVRUT041fDM4LHNwZWxsLDIxMDEyOCxzcGVsbCxBTFQtWCxDVFJMLUJVVFRPTjR8MzkjNCxBTFQtQyxBTFQtQlVUVE9ONXw0MCxzdW1tb25tb3VudCw3MjI4NiwsQUxULVYsQUxULUJVVFRPTjR8NDEjNCxDVFJMLVosU0hJRlQtQlVUVE9ONXw0MiM0LENUUkwtWCxTSElGVC1CVVRUT040fDQzLHNwZWxsLDQ4NzA3LHNwZWxsLENUUkwtQyxCVVRUT041fDQ0LHNwZWxsLDU2MjIyLHNwZWxsLEJVVFRPTjQsQ1RSTC1WfDQ1IzUsfDQ2IzUsfDQ3IzUsfDQ4IzUsfDQ5LHNwZWxsLDQ5OTk4LHNwZWxsLENUUkwtMSx8NTAsc3BlbGwsNDkwMzksc3BlbGwsQ1RSTC0yLHw1MSM0LENUUkwtMyx8NTIsc3BlbGwsNDg3NDMsc3BlbGwsQ1RSTC00LHw1MyxzcGVsbCwxMTE2NzMsc3BlbGwsQ1RSTC1RLHw1NCxzcGVsbCwzNzE0LHNwZWxsLENUUkwtRSx8NTUjNCxDVFJMLVIsfDU2LHNwZWxsLDYxOTk5LHNwZWxsLENUUkwtRix8NTcjNSx8NTgjNSx8NTkjNSx8NjAjNSx8NjEsc3BlbGwsNDI2NTAsc3BlbGwsU0hJRlQtMSx8NjIsc3BlbGwsMzQzMjk0LHNwZWxsLFNISUZULTIsfDYzIzQsU0hJRlQtMyx8NjQsc3BlbGwsNDY1ODQsc3BlbGwsU0hJRlQtNCx8NjUsc3BlbGwsNDk1NzYsc3BlbGwsU0hJRlQtUSx8NjYjNCxTSElGVC1FLHw2NyxzcGVsbCw1MTA1MixzcGVsbCxTSElGVC1SLHw2OCM0LFNISUZULUYsfDY5IzUsfDcwIzUsfDcxIzUsfDcyIzUsfDczIzUsfDc0IzUsfDc1IzUsfDc2IzUsfDc3IzUsfDc4IzUsfDc5IzUsfDgwIzUsfDgxIzUsfDgyIzUsfDgzIzUsfDg0IzUsfDg1IzUsfDg2IzUsfDg3IzUsfDg4IzUsfDg5IzUsfDkwIzUsfDkxIzUsfDkyIzUsfDkzIzUsfDk0IzUsfDk1IzUsfDk2IzUsfDk3IzUsfDk4IzUsfDk5IzUsfDEwMCM1LHwxMDEjNSx8MTAyIzUsfDEwMyM1LHwxMDQjNSx8MTA1IzUsfDEwNiM1LHwxMDcjNSx8MTA4IzUsfDEwOSM1LHwxMTAjNSx8MTExIzUsfDExMiM1LHwxMTMjNSx8MTE0IzUsfDExNSM1LHwxMTYjNSx8MTE3IzUsfDExOCM1LHwxMTkjNSx8MTIwIzUsfDEyMSxzcGVsbCwzNzI2MDgsc3BlbGwsLHwxMjIsc3BlbGwsMzcyNjEwLHNwZWxsLCx8MTIzLHNwZWxsLDM2MTU4NCxzcGVsbCwsfDEyNCxzcGVsbCw0MDMwOTIsc3BlbGwsLHwxMjUsc3BlbGwsNDI1NzgyLHNwZWxsLCx8MTI2IzUsfDEyNyM1LHwxMjgjNSx8MTI5IzUsfDEzMCM1LHwxMzEjNSx8MTMyIzUsfDEzMyM1LHwxMzQjNSx8MTM1IzUsfDEzNiM1LHwxMzcjNSx8MTM4IzUsfDEzOSM1LHwxNDAjNSx8MTQxIzUsfDE0MiM1LHwxNDMjNSx8MTQ0IzUsfDE0NSxtYWNybywxNDQsaXRlbSwsLFJXNW9ZVzVqWlZGdlRFUnlhVzVyVFdGamNtOD0sSTNOb2IzZDBiMjlzZEdsd0NpOWpZWE4wYzJWeGRXVnVZMlVnY21WelpYUTlZMjl0WW1GMElHbDBaVzA2TVRjeU1EWXpDZz09LGF8MTQ2LG1hY3JvLDE0NSxpdGVtLCwsUlc1b1lXNWpaVkZ2VEVSeWFXNXJUV0ZqY204PSxJM05vYjNkMGIyOXNkR2x3Q2k5allYTjBjMlZ4ZFdWdVkyVWdjbVZ6WlhROVkyOXRZbUYwSUdsMFpXMDZNVGN5TURZekNnPT0sYXwxNDcsbWFjcm8sMTQ2LGl0ZW0sLCxSR0Z0WVdkbElGQnZkQT09LEkzTm9iM2QwYjI5c2RHbHdDaTkxYzJVZ2FYUmxiVG95TkRFek1EZ0ssYXwxNDgsbWFjcm8sMTEjNCxVR3hoWTJWb2IyeGtaWEk9LFVHeGhZMlZvYjJ4a1pYSWdiV0ZqY204Z1ptOXlJR2wwWlcxeklHeHBhMlVnYm1sMGNtOGdZbTl2YzNRZ2IzSWdjMnh2ZHlCbVlXeHNJR05zYjJGckxnbz0sYXwxNDksbWFjcm8sMTQ4LGl0ZW0sLCxWSEpwYm10bGRDQXgsSTNOb2IzZDBiMjlzZEdsd0NpOTFjMlVnVzBCamRYSnpiM0pkTVRNSyxhfDE1MCxzcGVsbCw1OTU0NSxzcGVsbCwsfDE1MSM1LHwxNTIjNSx8MTUzIzUsfDE1NCM1LHwxNTUjNSx8MTU2IzUsfDE1NyM1LHwxNTgjNSx8MTU5IzUsfDE2MCM1LHwxNjEjNSx8MTYyIzUsfDE2MyM1LHwxNjQjNSx8MTY1IzUsfDE2NiM1LHwxNjcjNSx8MTY4IzUsfDE2OSM1LHwxNzAjNSx8MTcxIzUsfDE3MiM1LHwxNzMjNSx8MTc0IzUsfDE3NSM1LHwxNzYjNSx8MTc3IzUsfDE3OCM1LHwxNzkjNSx8MTgwIzUsfDE4MSM0LDUsfDE4MiM0LGAsfDE4MyM0LEYxLHwxODQjNCxGMix8MTg1IzQsRjMsfDE4NiM0LEY0LHwxODcjNSx8MTg4IzUsfDE4OSM1LHwxOTAjNSx8MTkxIzUsfDE5MiM1LA==
A5: Devourer | B5: MSxzcGVsbCw0NzM2NjIsc3BlbGwsMSx8MixzcGVsbCwxMjI2MDE5LHNwZWxsLDIsfDMsc3BlbGwsNDczNzI4LHNwZWxsLDMsfDQsc3BlbGwsMTI0NjU1NixzcGVsbCw0LHw1LHNwZWxsLDEyMTc2MDUsc3BlbGwsUSx8NixzcGVsbCwxMjQ2MTY3LHNwZWxsLEUsfDcsc3BlbGwsMTI0NTQxMixzcGVsbCxSLHw4LHNwZWxsLDE5ODc5MyxzcGVsbCxGLHw5IzUsfDEwIzUsfDExIzUsfDEyIzUsfDEzIzUsfDE0IzUsfDE1IzUsfDE2IzUsfDE3IzUsfDE4IzUsfDE5IzUsfDIwIzUsfDIxIzUsfDIyIzUsfDIzIzUsfDI0IzUsfDI1IzQsU0hJRlQtWix8MjYjNCxTSElGVC1YLHwyNyxzcGVsbCwyMDc2ODQsc3BlbGwsU0hJRlQtQyx8MjgjNCxTSElGVC1WLHwyOSxzcGVsbCwxOTg1ODksc3BlbGwsWix8MzAsc3BlbGwsMTIzNDc5NixzcGVsbCxYLHwzMSxzcGVsbCwxMjM0MTk1LHNwZWxsLEMsfDMyLHNwZWxsLDE4Mzc1MixzcGVsbCxWLHwzMyM1LHwzNCM1LHwzNSM1LHwzNiM1LHwzNyM0LEFMVC1aLHwzOCM0LEFMVC1YLENUUkwtQlVUVE9ONHwzOSM0LEFMVC1DLEFMVC1CVVRUT041fDQwIzQsQUxULVYsQUxULUJVVFRPTjR8NDEjNCxDVFJMLVosU0hJRlQtQlVUVE9ONXw0MiM0LENUUkwtWCxTSElGVC1CVVRUT040fDQzIzQsQ1RSTC1DLEJVVFRPTjV8NDQsc3BlbGwsMTg1MjQ1LHNwZWxsLEJVVFRPTjQsQ1RSTC1WfDQ1IzUsfDQ2IzUsfDQ3IzUsfDQ4IzUsfDQ5IzQsQ1RSTC0xLHw1MCM0LENUUkwtMix8NTEjNCxDVFJMLTMsfDUyIzQsQ1RSTC00LHw1MyxzcGVsbCwyNzgzMjYsc3BlbGwsQ1RSTC1RLHw1NCxzcGVsbCwyMTc4MzIsc3BlbGwsQ1RSTC1FLHw1NSxzcGVsbCwxOTY3MTgsc3BlbGwsQ1RSTC1SLHw1NiM0LENUUkwtRix8NTcjNSx8NTgjNSx8NTkjNSx8NjAjNSx8NjEjNCxTSElGVC0xLHw2MiM0LFNISUZULTIsfDYzIzQsU0hJRlQtMyx8NjQjNCxTSElGVC00LHw2NSM0LFNISUZULVEsfDY2IzQsU0hJRlQtRSx8Njcsc3BlbGwsMTg1MTIzLHNwZWxsLFNISUZULVIsfDY4LHNwZWxsLDEyNTE0MTcsc3BlbGwsU0hJRlQtRix8NjkjNSx8NzAjNSx8NzEjNSx8NzIjNSx8NzMjNSx8NzQjNSx8NzUjNSx8NzYjNSx8NzcjNSx8NzgjNSx8NzkjNSx8ODAjNSx8ODEjNSx8ODIjNSx8ODMjNSx8ODQjNSx8ODUjNSx8ODYjNSx8ODcjNSx8ODgjNSx8ODkjNSx8OTAjNSx8OTEjNSx8OTIjNSx8OTMjNSx8OTQjNSx8OTUjNSx8OTYjNSx8OTcjNSx8OTgjNSx8OTkjNSx8MTAwIzUsfDEwMSM1LHwxMDIjNSx8MTAzIzUsfDEwNCM1LHwxMDUjNSx8MTA2IzUsfDEwNyM1LHwxMDgjNSx8MTA5IzUsfDExMCM1LHwxMTEjNSx8MTEyIzUsfDExMyM1LHwxMTQjNSx8MTE1IzUsfDExNiM1LHwxMTcjNSx8MTE4IzUsfDExOSM1LHwxMjAjNSx8MTIxLHNwZWxsLDM3MjYwOCxzcGVsbCwsfDEyMixzcGVsbCwzNzI2MTAsc3BlbGwsLHwxMjMsc3BlbGwsMzYxNTg0LHNwZWxsLCx8MTI0IzUsfDEyNSxzcGVsbCw0MDMwOTIsc3BlbGwsLHwxMjYsc3BlbGwsNDI1NzgyLHNwZWxsLCx8MTI3IzUsfDEyOCM1LHwxMjkjNSx8MTMwIzUsfDEzMSM1LHwxMzIjNSx8MTMzIzUsfDEzNCM1LHwxMzUjNSx8MTM2IzUsfDEzNyM1LHwxMzgjNSx8MTM5IzUsfDE0MCM1LHwxNDEjNSx8MTQyIzUsfDE0MyM1LHwxNDQjNSx8MTQ1LG1hY3JvLDEyMzE0MTEsMTIzMTQxMSwsLFJXNW9ZVzVqWlZGdlRFaGxZV3gwYUUxaFkzSnYsSTNOb2IzZDBiMjlzZEdsd0NpOWpZWE4wSUZ0dWIyTnZiV0poZEYwZ1VtVmpkWEJsY21GMFpRb3ZZMkZ6ZEhObGNYVmxibU5sSUZ0amIyMWlZWFJkSUhKbGMyVjBQV052YldKaGRDQnBkR1Z0T2pJME5EZ3pPQT09LGF8MTQ2LG1hY3JvLDQjNCxSVzVvWVc1alpWRnZURVJ5YVc1clRXRmpjbTg9LEkzTm9iM2QwYjI5c2RHbHdDZz09LGF8MTQ3LG1hY3JvLDE0NixpdGVtLCwsUkdGdFlXZGxJRkJ2ZEE9PSxJM05vYjNkMGIyOXNkR2x3Q2k5MWMyVWdhWFJsYlRveU5ERXpNRGdLLGF8MTQ4LG1hY3JvLDExIzQsVUd4aFkyVm9iMnhrWlhJPSxVR3hoWTJWb2IyeGtaWElnYldGamNtOGdabTl5SUdsMFpXMXpJR3hwYTJVZ2JtbDBjbThnWW05dmMzUWdiM0lnYzJ4dmR5Qm1ZV3hzSUdOc2IyRnJMZ289LGF8MTQ5LG1hY3JvLDE0OCxpdGVtLCwsVkhKcGJtdGxkQ0F4LEkzTm9iM2QwYjI5c2RHbHdDaTkxYzJVZ1cwQmpkWEp6YjNKZE1UTUssYXwxNTAsc3BlbGwsNTg5ODQsc3BlbGwsLHwxNTEjNSx8MTUyIzUsfDE1MyM1LHwxNTQjNSx8MTU1IzUsfDE1NiM1LHwxNTcjNSx8MTU4IzUsfDE1OSM1LHwxNjAjNSx8MTYxIzUsfDE2MiM1LHwxNjMjNSx8MTY0IzUsfDE2NSM1LHwxNjYjNSx8MTY3IzUsfDE2OCM1LHwxNjkjNSx8MTcwIzUsfDE3MSM1LHwxNzIjNSx8MTczIzUsfDE3NCxtYWNybywwLCwsfDE3NSM1LHwxNzYjNSx8MTc3IzUsfDE3OCM1LHwxNzkjNSx8MTgwIzUs | C5: MCxfaGVhZGVyLGRlbW9uaHVudGVyLDE0ODAsLHwxLHNwZWxsLDQ3MzY2MixzcGVsbCwxLHwyLHNwZWxsLDEyMjYwMTksc3BlbGwsMix8MyxzcGVsbCw0NzM3Mjgsc3BlbGwsMyx8NCxzcGVsbCwxMjQ2NTU2LHNwZWxsLDQsfDUsc3BlbGwsMTIxNzYwNSxzcGVsbCxRLHw2LHNwZWxsLDEyNDYxNjcsc3BlbGwsRSx8NyxzcGVsbCwxMjQ1NDEyLHNwZWxsLFIsfDgsc3BlbGwsMTk4NzkzLHNwZWxsLEYsfDkjNSx8MTAjNSx8MTEjNSx8MTIjNSx8MTMjNSx8MTQjNSx8MTUjNSx8MTYjNSx8MTcjNSx8MTgjNSx8MTkjNSx8MjAjNSx8MjEjNSx8MjIjNSx8MjMjNSx8MjQjNSx8MjUjNCxTSElGVC1aLHwyNiM0LFNISUZULVgsfDI3LHNwZWxsLDIwNzY4NCxzcGVsbCxTSElGVC1DLHwyOCM0LFNISUZULVYsfDI5LHNwZWxsLDE5ODU4OSxzcGVsbCxaLHwzMCxzcGVsbCwxMjM0Nzk2LHNwZWxsLFgsfDMxLHNwZWxsLDEyMzQxOTUsc3BlbGwsQyx8MzIsc3BlbGwsMTgzNzUyLHNwZWxsLFYsfDMzIzUsfDM0IzUsfDM1IzUsfDM2IzUsfDM3IzQsQUxULVosQ1RSTC1CVVRUT041fDM4IzQsQUxULVgsQ1RSTC1CVVRUT040fDM5IzQsQUxULUMsQUxULUJVVFRPTjV8NDAsc3VtbW9ubW91bnQsMTIzNDMwMywsQUxULVYsQUxULUJVVFRPTjR8NDEjNCxDVFJMLVosU0hJRlQtQlVUVE9ONXw0MiM0LENUUkwtWCxTSElGVC1CVVRUT040fDQzIzQsQ1RSTC1DLEJVVFRPTjV8NDQsc3BlbGwsMTg1MjQ1LHNwZWxsLEJVVFRPTjQsQ1RSTC1WfDQ1IzUsfDQ2IzUsfDQ3IzUsfDQ4IzUsfDQ5IzQsQ1RSTC0xLHw1MCM0LENUUkwtMix8NTEjNCxDVFJMLTMsfDUyIzQsQ1RSTC00LHw1MyxzcGVsbCwyNzgzMjYsc3BlbGwsQ1RSTC1RLHw1NCxzcGVsbCwyMTc4MzIsc3BlbGwsQ1RSTC1FLHw1NSxzcGVsbCwxOTY3MTgsc3BlbGwsQ1RSTC1SLHw1NiM0LENUUkwtRix8NTcjNSx8NTgjNSx8NTkjNSx8NjAjNSx8NjEjNCxTSElGVC0xLHw2MiM0LFNISUZULTIsfDYzIzQsU0hJRlQtMyx8NjQjNCxTSElGVC00LHw2NSM0LFNISUZULVEsfDY2IzQsU0hJRlQtRSx8Njcsc3BlbGwsMTg1MTIzLHNwZWxsLFNISUZULVIsfDY4LHNwZWxsLDEyNTE0MTcsc3BlbGwsU0hJRlQtRix8NjkjNSx8NzAjNSx8NzEjNSx8NzIjNSx8NzMjNSx8NzQjNSx8NzUjNSx8NzYjNSx8NzcjNSx8NzgjNSx8NzkjNSx8ODAjNSx8ODEjNSx8ODIjNSx8ODMjNSx8ODQjNSx8ODUjNSx8ODYjNSx8ODcjNSx8ODgjNSx8ODkjNSx8OTAjNSx8OTEjNSx8OTIjNSx8OTMjNSx8OTQjNSx8OTUjNSx8OTYjNSx8OTcjNSx8OTgjNSx8OTkjNSx8MTAwIzUsfDEwMSM1LHwxMDIjNSx8MTAzIzUsfDEwNCM1LHwxMDUjNSx8MTA2IzUsfDEwNyM1LHwxMDgjNSx8MTA5IzUsfDExMCM1LHwxMTEjNSx8MTEyIzUsfDExMyM1LHwxMTQjNSx8MTE1IzUsfDExNiM1LHwxMTcjNSx8MTE4IzUsfDExOSM1LHwxMjAjNSx8MTIxLHNwZWxsLDM3MjYwOCxzcGVsbCwsfDEyMixzcGVsbCwzNzI2MTAsc3BlbGwsLHwxMjMsc3BlbGwsMzYxNTg0LHNwZWxsLCx8MTI0IzUsfDEyNSxzcGVsbCw0MDMwOTIsc3BlbGwsLHwxMjYsc3BlbGwsNDI1NzgyLHNwZWxsLCx8MTI3IzUsfDEyOCM1LHwxMjkjNSx8MTMwIzUsfDEzMSM1LHwxMzIjNSx8MTMzIzUsfDEzNCM1LHwxMzUjNSx8MTM2IzUsfDEzNyM1LHwxMzgjNSx8MTM5IzUsfDE0MCM1LHwxNDEjNSx8MTQyIzUsfDE0MyM1LHwxNDQjNSx8MTQ1LG1hY3JvLDEyMzE0MTEsMTIzMTQxMSwsLFJXNW9ZVzVqWlZGdlRFaGxZV3gwYUUxaFkzSnYsSTNOb2IzZDBiMjlzZEdsd0NpOWpZWE4wSUZ0dWIyTnZiV0poZEYwZ1VtVmpkWEJsY21GMFpRb3ZZMkZ6ZEhObGNYVmxibU5sSUZ0amIyMWlZWFJkSUhKbGMyVjBQV052YldKaGRDQnBkR1Z0T2pJME5EZ3pPQT09LGF8MTQ2LG1hY3JvLDE0NSxpdGVtLCwsUlc1b1lXNWpaVkZ2VEVSeWFXNXJUV0ZqY204PSxJM05vYjNkMGIyOXNkR2x3Q2k5allYTjBjMlZ4ZFdWdVkyVWdjbVZ6WlhROVkyOXRZbUYwSUdsMFpXMDZNVGN5TURZekNnPT0sYXwxNDcsbWFjcm8sMTQ2LGl0ZW0sLCxSR0Z0WVdkbElGQnZkQT09LEkzTm9iM2QwYjI5c2RHbHdDaTkxYzJVZ2FYUmxiVG95TkRFek1EZ0ssYXwxNDgsbWFjcm8sMTEjNCxVR3hoWTJWb2IyeGtaWEk9LFVHeGhZMlZvYjJ4a1pYSWdiV0ZqY204Z1ptOXlJR2wwWlcxeklHeHBhMlVnYm1sMGNtOGdZbTl2YzNRZ2IzSWdjMnh2ZHlCbVlXeHNJR05zYjJGckxnbz0sYXwxNDksbWFjcm8sMTQ4LGl0ZW0sLCxWSEpwYm10bGRDQXgsSTNOb2IzZDBiMjlzZEdsd0NpOTFjMlVnVzBCamRYSnpiM0pkTVRNSyxhfDE1MCxzcGVsbCw1ODk4NCxzcGVsbCwsfDE1MSM1LHwxNTIjNSx8MTUzIzUsfDE1NCM1LHwxNTUjNSx8MTU2IzUsfDE1NyM1LHwxNTgjNSx8MTU5IzUsfDE2MCM1LHwxNjEjNSx8MTYyIzUsfDE2MyM1LHwxNjQjNSx8MTY1IzUsfDE2NiM1LHwxNjcjNSx8MTY4IzUsfDE2OSM1LHwxNzAjNSx8MTcxIzUsfDE3MiM1LHwxNzMjNSx8MTc0LG1hY3JvLDAsLCx8MTc1IzUsfDE3NiM1LHwxNzcjNSx8MTc4IzUsfDE3OSM1LHwxODAjNSx8MTgxIzQsNSx8MTgyIzQsYCx8MTgzIzQsRjEsfDE4NCM0LEYyLHwxODUjNCxGMyx8MTg2IzQsRjQsfDE4NyM0LEY1LHwxODgjNCxGNix8MTg5IzUsfDE5MCM1LHwxOTEjNSx8MTkyIzUs
A6: Havoc | B6: MSxzcGVsbCwxNjI3OTQsc3BlbGwsMSx8MixzcGVsbCwxODg0OTksc3BlbGwsMix8MyxzcGVsbCwxOTgwMTMsc3BlbGwsMyx8NCxzcGVsbCwyNTg5MjAsc3BlbGwsNCx8NSxzcGVsbCwyNTg4NjAsc3BlbGwsUSx8NixzcGVsbCwzNzA5NjUsc3BlbGwsRSx8NyxzcGVsbCwyMzI4OTMsc3BlbGwsUix8OCxzcGVsbCwxOTg3OTMsc3BlbGwsRix8OSM1LHwxMCM1LHwxMSM1LHwxMiM1LHwxMyM1LHwxNCM1LHwxNSM1LHwxNiM1LHwxNyM1LHwxOCM1LHwxOSM1LHwyMCM1LHwyMSM1LHwyMiM1LHwyMyM1LHwyNCM1LHwyNSM0LFNISUZULVosfDI2IzQsU0hJRlQtWCx8MjcsbWFjcm8sMjA3Njg0LDIwNzY4NCxTSElGVC1DLCxVMmxuYVd3Z2IyWWdUV2x6WlhKNUlDaEhjbTkxYm1RcCxJM05vYjNkMGIyOXNkR2x3SUZOcFoybHNJRzltSUUxcGMyVnllUW92WTJGemRDQmJRR04xY25OdmNsMGdVMmxuYVd3Z2IyWWdUV2x6WlhKNUNnPT0sY3wyOCM0LFNISUZULVYsfDI5LHNwZWxsLDE5ODU4OSxzcGVsbCxaLHwzMCxzcGVsbCwxOTUwNzIsc3BlbGwsWCx8MzEsc3BlbGwsMTc5MDU3LHNwZWxsLEMsfDMyLHNwZWxsLDE4Mzc1MixzcGVsbCxWLHwzMyM1LHwzNCM1LHwzNSM1LHwzNiM1LHwzNyM0LEFMVC1aLHwzOCM0LEFMVC1YLENUUkwtQlVUVE9ONHwzOSM0LEFMVC1DLEFMVC1CVVRUT041fDQwIzQsQUxULVYsQUxULUJVVFRPTjR8NDEjNCxDVFJMLVosU0hJRlQtQlVUVE9ONXw0MiM0LENUUkwtWCxTSElGVC1CVVRUT040fDQzIzQsQ1RSTC1DLEJVVFRPTjV8NDQsc3BlbGwsMTg1MjQ1LHNwZWxsLEJVVFRPTjQsQ1RSTC1WfDQ1LHNwZWxsLDE4ODUwMSxzcGVsbCwsfDQ2IzUsfDQ3IzUsfDQ4LG1hY3JvLDEyNyM0LFQzVjBabWwwSUVOdmJHeGxZM1JwYjI0PSxJM0JzZFcxaVpYSTZiM1YwWm1sMENpOWpiR2xqYXlCUVRFMVNYMDlWVkVaSlZBPT0sY3w0OSM0LENUUkwtMSx8NTAjNCxDVFJMLTIsfDUxIzQsQ1RSTC0zLHw1MiM0LENUUkwtNCx8NTMsc3BlbGwsMjc4MzI2LHNwZWxsLENUUkwtUSx8NTQsc3BlbGwsMjE3ODMyLHNwZWxsLENUUkwtRSx8NTUsc3BlbGwsMTk2NzE4LHNwZWxsLENUUkwtUix8NTYjNCxDVFJMLUYsfDU3IzUsfDU4IzUsfDU5IzUsfDYwIzUsfDYxLG1hY3JvLDE5MTQyNywxOTE0MjcsU0hJRlQtMSwsVFdWMFlXMXZjbkJvYjNOcGN5QW9SM0p2ZFc1a0tRPT0sSTNOb2IzZDBiMjlzZEdsd0lFMWxkR0Z0YjNKd2FHOXphWE1LTDJOaGMzUWdXMEJqZFhKemIzSmRJRTFsZEdGdGIzSndhRzl6YVhNSyxjfDYyIzQsU0hJRlQtMix8NjMjNCxTSElGVC0zLHw2NCM0LFNISUZULTQsfDY1IzQsU0hJRlQtUSx8NjYjNCxTSElGVC1FLHw2NyxzcGVsbCwxODUxMjMsc3BlbGwsU0hJRlQtUix8Njgsc3BlbGwsMTg4NTAxLHNwZWxsLFNISUZULUYsfDY5IzUsfDcwIzUsfDcxIzUsfDcyIzUsfDczIzUsfDc0IzUsfDc1IzUsfDc2IzUsfDc3IzUsfDc4IzUsfDc5IzUsfDgwIzUsfDgxIzUsfDgyIzUsfDgzIzUsfDg0IzUsfDg1IzUsfDg2IzUsfDg3IzUsfDg4IzUsfDg5IzUsfDkwIzUsfDkxIzUsfDkyIzUsfDkzIzUsfDk0IzUsfDk1IzUsfDk2IzUsfDk3IzUsfDk4IzUsfDk5IzUsfDEwMCM1LHwxMDEjNSx8MTAyIzUsfDEwMyM1LHwxMDQjNSx8MTA1IzUsfDEwNiM1LHwxMDcjNSx8MTA4IzUsfDEwOSM1LHwxMTAjNSx8MTExIzUsfDExMiM1LHwxMTMjNSx8MTE0IzUsfDExNSM1LHwxMTYjNSx8MTE3IzUsfDExOCM1LHwxMTkjNSx8MTIwIzUsfDEyMSxzcGVsbCwzNzI2MDgsc3BlbGwsLHwxMjIsc3BlbGwsMzcyNjEwLHNwZWxsLCx8MTIzLHNwZWxsLDM2MTU4NCxzcGVsbCwsfDEyNCM1LHwxMjUsc3BlbGwsNDAzMDkyLHNwZWxsLCx8MTI2LHNwZWxsLDQyNTc4MixzcGVsbCwsfDEyNyM1LHwxMjgjNSx8MTI5IzUsfDEzMCM1LHwxMzEjNSx8MTMyIzUsfDEzMyM1LHwxMzQjNSx8MTM1IzUsfDEzNiM1LHwxMzcjNSx8MTM4IzUsfDEzOSM1LHwxNDAjNSx8MTQxIzUsfDE0MiM1LHwxNDMjNSx8MTQ0IzUsfDE0NSxtYWNybywxMjMxNDExLDEyMzE0MTEsLCxSVzVvWVc1alpWRnZURWhsWVd4MGFFMWhZM0p2LEkzTm9iM2QwYjI5c2RHbHdDaTlqWVhOMElGdHViMk52YldKaGRGMGdVbVZqZFhCbGNtRjBaUW92WTJGemRITmxjWFZsYm1ObElGdGpiMjFpWVhSZElISmxjMlYwUFdOdmJXSmhkQ0JwZEdWdE9qSTBORGd6T0E9PSxhfDE0NiM1LHwxNDcsbWFjcm8sMTQ2LGl0ZW0sLCxSR0Z0WVdkbElGQnZkQT09LEkzTm9iM2QwYjI5c2RHbHdDaTkxYzJVZ2FYUmxiVG95TkRFek1EZ0ssYXwxNDgsbWFjcm8sMTEjNCxVR3hoWTJWb2IyeGtaWEk9LFVHeGhZMlZvYjJ4a1pYSWdiV0ZqY204Z1ptOXlJR2wwWlcxeklHeHBhMlVnYm1sMGNtOGdZbTl2YzNRZ2IzSWdjMnh2ZHlCbVlXeHNJR05zYjJGckxnbz0sYXwxNDksbWFjcm8sMTQ4LGl0ZW0sLCxWSEpwYm10bGRDQXgsSTNOb2IzZDBiMjlzZEdsd0NpOTFjMlVnVzBCamRYSnpiM0pkTVRNSyxhfDE1MCxzcGVsbCw1ODk4NCxzcGVsbCwsfDE1MSM1LHwxNTIjNSx8MTUzIzUsfDE1NCM1LHwxNTUjNSx8MTU2IzUsfDE1NyM1LHwxNTgjNSx8MTU5IzUsfDE2MCM1LHwxNjEjNSx8MTYyIzUsfDE2MyM1LHwxNjQjNSx8MTY1IzUsfDE2NiM1LHwxNjcjNSx8MTY4IzUsfDE2OSM1LHwxNzAjNSx8MTcxIzUsfDE3MiM1LHwxNzMjNSx8MTc0IzUsfDE3NSM1LHwxNzYjNSx8MTc3IzUsfDE3OCM1LHwxNzkjNSx8MTgwIzUs | C6: MCxfaGVhZGVyLGRlbW9uaHVudGVyLDU3NywsfDEsc3BlbGwsMTYyNzk0LHNwZWxsLDEsfDIsc3BlbGwsMTg4NDk5LHNwZWxsLDIsfDMsc3BlbGwsMTk4MDEzLHNwZWxsLDMsfDQsc3BlbGwsMjU4OTIwLHNwZWxsLDQsfDUsc3BlbGwsMjU4ODYwLHNwZWxsLFEsfDYsc3BlbGwsMzcwOTY1LHNwZWxsLEUsfDcsc3BlbGwsMjMyODkzLHNwZWxsLFIsfDgsc3BlbGwsMTk4NzkzLHNwZWxsLEYsfDkjNSx8MTAjNSx8MTEjNSx8MTIjNSx8MTMjNSx8MTQjNSx8MTUjNSx8MTYjNSx8MTcjNSx8MTgjNSx8MTkjNSx8MjAjNSx8MjEjNSx8MjIjNSx8MjMjNSx8MjQjNSx8MjUjNCxTSElGVC1aLHwyNiM0LFNISUZULVgsfDI3LG1hY3JvLDIwNzY4NCwyMDc2ODQsU0hJRlQtQywsVTJsbmFXd2diMllnVFdselpYSjVJQ2hIY205MWJtUXAsSTNOb2IzZDBiMjlzZEdsd0lGTnBaMmxzSUc5bUlFMXBjMlZ5ZVFvdlkyRnpkQ0JiUUdOMWNuTnZjbDBnVTJsbmFXd2diMllnVFdselpYSjVDZz09LGN8MjgjNCxTSElGVC1WLHwyOSxzcGVsbCwxOTg1ODksc3BlbGwsWix8MzAsc3BlbGwsMTk1MDcyLHNwZWxsLFgsfDMxLHNwZWxsLDE3OTA1NyxzcGVsbCxDLHwzMixzcGVsbCwxODM3NTIsc3BlbGwsVix8MzMjNSx8MzQjNSx8MzUjNSx8MzYjNSx8MzcjNCxBTFQtWixDVFJMLUJVVFRPTjV8MzgjNCxBTFQtWCxDVFJMLUJVVFRPTjR8MzkjNCxBTFQtQyxBTFQtQlVUVE9ONXw0MCxzdW1tb25tb3VudCw5NzUwMSwsQUxULVYsQUxULUJVVFRPTjR8NDEjNCxDVFJMLVosU0hJRlQtQlVUVE9ONXw0MiM0LENUUkwtWCxTSElGVC1CVVRUT040fDQzIzQsQ1RSTC1DLEJVVFRPTjV8NDQsc3BlbGwsMTg1MjQ1LHNwZWxsLEJVVFRPTjQsQ1RSTC1WfDQ1IzUsfDQ2IzUsfDQ3IzUsfDQ4LG1hY3JvLDEyNyM0LFQzVjBabWwwSUVOdmJHeGxZM1JwYjI0PSxJM0JzZFcxaVpYSTZiM1YwWm1sMENpOWpiR2xqYXlCUVRFMVNYMDlWVkVaSlZBPT0sY3w0OSM0LENUUkwtMSx8NTAjNCxDVFJMLTIsfDUxIzQsQ1RSTC0zLHw1MiM0LENUUkwtNCx8NTMsc3BlbGwsMjc4MzI2LHNwZWxsLENUUkwtUSx8NTQsc3BlbGwsMjE3ODMyLHNwZWxsLENUUkwtRSx8NTUsc3BlbGwsMTk2NzE4LHNwZWxsLENUUkwtUix8NTYjNCxDVFJMLUYsfDU3IzUsfDU4IzUsfDU5IzUsfDYwIzUsfDYxLG1hY3JvLDE5MTQyNywxOTE0MjcsU0hJRlQtMSwsVFdWMFlXMXZjbkJvYjNOcGN5QW9SM0p2ZFc1a0tRPT0sSTNOb2IzZDBiMjlzZEdsd0lFMWxkR0Z0YjNKd2FHOXphWE1LTDJOaGMzUWdXMEJqZFhKemIzSmRJRTFsZEdGdGIzSndhRzl6YVhNSyxjfDYyIzQsU0hJRlQtMix8NjMjNCxTSElGVC0zLHw2NCM0LFNISUZULTQsfDY1IzQsU0hJRlQtUSx8NjYjNCxTSElGVC1FLHw2NyxzcGVsbCwxODUxMjMsc3BlbGwsU0hJRlQtUix8Njgsc3BlbGwsMTg4NTAxLHNwZWxsLFNISUZULUYsfDY5IzUsfDcwIzUsfDcxIzUsfDcyIzUsfDczIzUsfDc0IzUsfDc1IzUsfDc2IzUsfDc3IzUsfDc4IzUsfDc5IzUsfDgwIzUsfDgxIzUsfDgyIzUsfDgzIzUsfDg0IzUsfDg1IzUsfDg2IzUsfDg3IzUsfDg4IzUsfDg5IzUsfDkwIzUsfDkxIzUsfDkyIzUsfDkzIzUsfDk0IzUsfDk1IzUsfDk2IzUsfDk3IzUsfDk4IzUsfDk5IzUsfDEwMCM1LHwxMDEjNSx8MTAyIzUsfDEwMyM1LHwxMDQjNSx8MTA1IzUsfDEwNiM1LHwxMDcjNSx8MTA4IzUsfDEwOSM1LHwxMTAjNSx8MTExIzUsfDExMiM1LHwxMTMjNSx8MTE0IzUsfDExNSM1LHwxMTYjNSx8MTE3IzUsfDExOCM1LHwxMTkjNSx8MTIwIzUsfDEyMSxzcGVsbCwzNzI2MDgsc3BlbGwsLHwxMjIsc3BlbGwsMzcyNjEwLHNwZWxsLCx8MTIzLHNwZWxsLDM2MTU4NCxzcGVsbCwsfDEyNCM1LHwxMjUsc3BlbGwsNDAzMDkyLHNwZWxsLCx8MTI2LHNwZWxsLDQyNTc4MixzcGVsbCwsfDEyNyM1LHwxMjgjNSx8MTI5IzUsfDEzMCM1LHwxMzEjNSx8MTMyIzUsfDEzMyM1LHwxMzQjNSx8MTM1IzUsfDEzNiM1LHwxMzcjNSx8MTM4IzUsfDEzOSM1LHwxNDAjNSx8MTQxIzUsfDE0MiM1LHwxNDMjNSx8MTQ0IzUsfDE0NSxtYWNybywxMjMxNDExLDEyMzE0MTEsLCxSVzVvWVc1alpWRnZURWhsWVd4MGFFMWhZM0p2LEkzTm9iM2QwYjI5c2RHbHdDaTlqWVhOMElGdHViMk52YldKaGRGMGdVbVZqZFhCbGNtRjBaUW92WTJGemRITmxjWFZsYm1ObElGdGpiMjFpWVhSZElISmxjMlYwUFdOdmJXSmhkQ0JwZEdWdE9qSTBORGd6T0E9PSxhfDE0NiM1LHwxNDcsbWFjcm8sMTQ2LGl0ZW0sLCxSR0Z0WVdkbElGQnZkQT09LEkzTm9iM2QwYjI5c2RHbHdDaTkxYzJVZ2FYUmxiVG95TkRFek1EZ0ssYXwxNDgsbWFjcm8sMTEjNCxVR3hoWTJWb2IyeGtaWEk9LFVHeGhZMlZvYjJ4a1pYSWdiV0ZqY204Z1ptOXlJR2wwWlcxeklHeHBhMlVnYm1sMGNtOGdZbTl2YzNRZ2IzSWdjMnh2ZHlCbVlXeHNJR05zYjJGckxnbz0sYXwxNDksbWFjcm8sMTQ4LGl0ZW0sLCxWSEpwYm10bGRDQXgsSTNOb2IzZDBiMjlzZEdsd0NpOTFjMlVnVzBCamRYSnpiM0pkTVRNSyxhfDE1MCxzcGVsbCw1ODk4NCxzcGVsbCwsfDE1MSM1LHwxNTIjNSx8MTUzIzUsfDE1NCM1LHwxNTUjNSx8MTU2IzUsfDE1NyM1LHwxNTgjNSx8MTU5IzUsfDE2MCM1LHwxNjEjNSx8MTYyIzUsfDE2MyM1LHwxNjQjNSx8MTY1IzUsfDE2NiM1LHwxNjcjNSx8MTY4IzUsfDE2OSM1LHwxNzAjNSx8MTcxIzUsfDE3MiM1LHwxNzMjNSx8MTc0IzUsfDE3NSM1LHwxNzYjNSx8MTc3IzUsfDE3OCM1LHwxNzkjNSx8MTgwIzUsfDE4MSM0LDUsfDE4MiM0LGAsfDE4MyM0LEYxLHwxODQjNCxGMix8MTg1IzQsRjMsfDE4NiM0LEY0LHwxODcjNSx8MTg4IzUsfDE4OSM1LHwxOTAjNSx8MTkxIzUsfDE5MiM1LA==
A7: Vengeance | B7: MSxzcGVsbCwyNjM2NDIsc3BlbGwsMSx8MixzcGVsbCwyMjg0Nzcsc3BlbGwsMix8MyxzcGVsbCwyNDc0NTQsc3BlbGwsMyx8NCxzcGVsbCwyNTg5MjAsc3BlbGwsNCx8NSxzcGVsbCwyMDM3MjAsc3BlbGwsUSx8NixtYWNybywyMDQ1OTYsMjA0NTk2LEUsLFl3PT0sSTNOb2IzZDBiMjlzZEdsd0NpOWpZWE4wSUZ0QVkzVnljMjl5WFZOcFoybHNJRzltSUVac1lXMWxDZz09LGN8NyxzcGVsbCwyMzI4OTMsc3BlbGwsUix8OCxzcGVsbCwxOTg3OTMsc3BlbGwsRix8OSM1LHwxMCM1LHwxMSM1LHwxMiM1LHwxMyM1LHwxNCM1LHwxNSM1LHwxNiM1LHwxNyM1LHwxOCM1LHwxOSM1LHwyMCM1LHwyMSM1LHwyMiM1LHwyMyM1LHwyNCM1LHwyNSM0LFNISUZULVosfDI2IzQsU0hJRlQtWCx8Mjcsc3BlbGwsMjA3Njg0LHNwZWxsLFNISUZULUMsfDI4IzQsU0hJRlQtVix8Mjksc3BlbGwsMjA0MDIxLHNwZWxsLFosfDMwLG1hY3JvLDE4OTExMCwxODkxMTAsWCwsWTNWeWMyOXlJR2x1Wm1WeSxJM05vYjNkMGIyOXNkR2x3Q2k5allYTjBJRnRBWTNWeWMyOXlYVWx1Wm1WeWJtRnNJRk4wY21sclpRbz0sY3wzMSxzcGVsbCwxNzkwNTcsc3BlbGwsQyx8MzIsc3BlbGwsMTgzNzUyLHNwZWxsLFYsfDMzIzUsfDM0IzUsfDM1IzUsfDM2IzUsfDM3IzQsQUxULVosQ1RSTC1CVVRUT041fDM4IzQsQUxULVgsQ1RSTC1CVVRUT040fDM5IzQsQUxULUMsQUxULUJVVFRPTjV8NDAjNCxBTFQtVixBTFQtQlVUVE9ONHw0MSM0LENUUkwtWixTSElGVC1CVVRUT041fDQyIzQsQ1RSTC1YLFNISUZULUJVVFRPTjR8NDMjNCxDVFJMLUMsQlVUVE9ONXw0NCxzcGVsbCwxODUyNDUsc3BlbGwsQ1RSTC1WLEJVVFRPTjR8NDUjNSx8NDYjNSx8NDcjNSx8NDgjNSx8NDkjNCxDVFJMLTEsfDUwIzQsQ1RSTC0yLHw1MSM0LENUUkwtMyx8NTIjNCxDVFJMLTQsfDUzLHNwZWxsLDI3ODMyNixzcGVsbCxDVFJMLVEsfDU0LHNwZWxsLDIxNzgzMixzcGVsbCxDVFJMLUUsfDU1LHNwZWxsLDE5NjcxOCxzcGVsbCxDVFJMLVIsfDU2IzQsQ1RSTC1GLHw1NyM1LHw1OCM1LHw1OSM1LHw2MCM1LHw2MSxzcGVsbCwxODc4Mjcsc3BlbGwsU0hJRlQtMSx8NjIsbWFjcm8sMzkwMTYzLDM5MDE2MyxTSElGVC0yLCxVMmxuYVd3Z2IyWWdVM0JwZEdVPSxJM05vYjNkMGIyOXNkR2x3SUZOcFoybHNJRzltSUZOd2FYUmxDaTlqWVhOMElGdEFZM1Z5YzI5eVhTQlRhV2RwYkNCdlppQlRjR2wwWlFvPSxjfDYzLHNwZWxsLDIwNzQwNyxzcGVsbCxTSElGVC0zLHw2NCxzcGVsbCwyMTIwODQsc3BlbGwsU0hJRlQtNCx8NjUjNCxTSElGVC1RLHw2NixzcGVsbCwyMDIxMzcsc3BlbGwsU0hJRlQtRSx8Njcsc3BlbGwsMjA0MTU3LHNwZWxsLFNISUZULVIsfDY4LHNwZWxsLDE4ODUwMSxzcGVsbCxTSElGVC1GLHw2OSM1LHw3MCM1LHw3MSM1LHw3MiM1LHw3MyM1LHw3NCM1LHw3NSM1LHw3NiM1LHw3NyM1LHw3OCM1LHw3OSM1LHw4MCM1LHw4MSM1LHw4MiM1LHw4MyM1LHw4NCM1LHw4NSM1LHw4NiM1LHw4NyM1LHw4OCM1LHw4OSM1LHw5MCM1LHw5MSM1LHw5MiM1LHw5MyM1LHw5NCM1LHw5NSM1LHw5NiM1LHw5NyM1LHw5OCM1LHw5OSM1LHwxMDAjNSx8MTAxIzUsfDEwMiM1LHwxMDMjNSx8MTA0IzUsfDEwNSM1LHwxMDYjNSx8MTA3IzUsfDEwOCM1LHwxMDkjNSx8MTEwIzUsfDExMSM1LHwxMTIjNSx8MTEzIzUsfDExNCM1LHwxMTUjNSx8MTE2IzUsfDExNyM1LHwxMTgjNSx8MTE5IzUsfDEyMCM1LHwxMjEsc3BlbGwsMzcyNjA4LHNwZWxsLCx8MTIyLHNwZWxsLDM3MjYxMCxzcGVsbCwsfDEyMyxzcGVsbCwzNjE1ODQsc3BlbGwsLHwxMjQjNSx8MTI1LHNwZWxsLDQwMzA5MixzcGVsbCwsfDEyNixzcGVsbCw0MjU3ODIsc3BlbGwsLHwxMjcjNSx8MTI4IzUsfDEyOSM1LHwxMzAjNSx8MTMxIzUsfDEzMiM1LHwxMzMjNSx8MTM0IzUsfDEzNSM1LHwxMzYjNSx8MTM3IzUsfDEzOCM1LHwxMzkjNSx8MTQwIzUsfDE0MSM1LHwxNDIjNSx8MTQzIzUsfDE0NCM1LHwxNDUsbWFjcm8sMTIzMTQxMSwxMjMxNDExLCwsUlc1b1lXNWpaVkZ2VEVobFlXeDBhRTFoWTNKdixJM05vYjNkMGIyOXNkR2x3Q2k5allYTjBJRnR1YjJOdmJXSmhkRjBnVW1WamRYQmxjbUYwWlFvdlkyRnpkSE5sY1hWbGJtTmxJRnRqYjIxaVlYUmRJSEpsYzJWMFBXTnZiV0poZENCcGRHVnRPakkwTkRnek9BPT0sYXwxNDYjNSx8MTQ3LGl0ZW0sMjEyMjY0LCwsfDE0OCM1LHwxNDksbWFjcm8sMTQ4LGl0ZW0sLCxWSEpwYm10bGRDQXgsSTNOb2IzZDBiMjlzZEdsd0NpOTFjMlVnVzBCamRYSnpiM0pkTVRNSyxhfDE1MCxzcGVsbCw1ODk4NCxzcGVsbCwsfDE1MSM1LHwxNTIjNSx8MTUzIzUsfDE1NCM1LHwxNTUjNSx8MTU2IzUsfDE1NyM1LHwxNTgjNSx8MTU5IzUsfDE2MCM1LHwxNjEjNSx8MTYyIzUsfDE2MyM1LHwxNjQjNSx8MTY1IzUsfDE2NiM1LHwxNjcjNSx8MTY4IzUsfDE2OSM1LHwxNzAjNSx8MTcxIzUsfDE3MiM1LHwxNzMjNSx8MTc0IzUsfDE3NSM1LHwxNzYjNSx8MTc3IzUsfDE3OCM1LHwxNzkjNSx8MTgwIzUs | C7: MCxfaGVhZGVyLGRlbW9uaHVudGVyLDU4MSwsfDEsc3BlbGwsMjYzNjQyLHNwZWxsLDEsfDIsc3BlbGwsMjI4NDc3LHNwZWxsLDIsfDMsc3BlbGwsMjQ3NDU0LHNwZWxsLDMsfDQsc3BlbGwsMjU4OTIwLHNwZWxsLDQsfDUsc3BlbGwsMjAzNzIwLHNwZWxsLFEsfDYsbWFjcm8sMjA0NTk2LDIwNDU5NixFLCxZdz09LEkzTm9iM2QwYjI5c2RHbHdDaTlqWVhOMElGdEFZM1Z5YzI5eVhWTnBaMmxzSUc5bUlFWnNZVzFsQ2c9PSxjfDcsc3BlbGwsMjMyODkzLHNwZWxsLFIsfDgsc3BlbGwsMTk4NzkzLHNwZWxsLEYsfDkjNSx8MTAjNSx8MTEjNSx8MTIjNSx8MTMjNSx8MTQjNSx8MTUjNSx8MTYjNSx8MTcjNSx8MTgjNSx8MTkjNSx8MjAjNSx8MjEjNSx8MjIjNSx8MjMjNSx8MjQjNSx8MjUjNCxTSElGVC1aLHwyNiM0LFNISUZULVgsfDI3LHNwZWxsLDIwNzY4NCxzcGVsbCxTSElGVC1DLHwyOCM0LFNISUZULVYsfDI5LHNwZWxsLDIwNDAyMSxzcGVsbCxaLHwzMCxtYWNybywxODkxMTAsMTg5MTEwLFgsLFkzVnljMjl5SUdsdVptVnksSTNOb2IzZDBiMjlzZEdsd0NpOWpZWE4wSUZ0QVkzVnljMjl5WFVsdVptVnlibUZzSUZOMGNtbHJaUW89LGN8MzEsc3BlbGwsMTc5MDU3LHNwZWxsLEMsfDMyLHNwZWxsLDE4Mzc1MixzcGVsbCxWLHwzMyM1LHwzNCM1LHwzNSM1LHwzNiM1LHwzNyM0LEFMVC1aLENUUkwtQlVUVE9ONXwzOCM0LEFMVC1YLENUUkwtQlVUVE9ONHwzOSM0LEFMVC1DLEFMVC1CVVRUT041fDQwLHN1bW1vbm1vdW50LDk3NTAxLCxBTFQtVixBTFQtQlVUVE9ONHw0MSM0LENUUkwtWixTSElGVC1CVVRUT041fDQyIzQsQ1RSTC1YLFNISUZULUJVVFRPTjR8NDMjNCxDVFJMLUMsQlVUVE9ONXw0NCxzcGVsbCwxODUyNDUsc3BlbGwsQlVUVE9ONCxDVFJMLVZ8NDUjNSx8NDYjNSx8NDcjNSx8NDgjNSx8NDkjNCxDVFJMLTEsfDUwIzQsQ1RSTC0yLHw1MSM0LENUUkwtMyx8NTIjNCxDVFJMLTQsfDUzLHNwZWxsLDI3ODMyNixzcGVsbCxDVFJMLVEsfDU0LHNwZWxsLDIxNzgzMixzcGVsbCxDVFJMLUUsfDU1LHNwZWxsLDE5NjcxOCxzcGVsbCxDVFJMLVIsfDU2IzQsQ1RSTC1GLHw1NyM1LHw1OCM1LHw1OSM1LHw2MCM1LHw2MSxzcGVsbCwxODc4Mjcsc3BlbGwsU0hJRlQtMSx8NjIsbWFjcm8sMzkwMTYzLDM5MDE2MyxTSElGVC0yLCxVMmxuYVd3Z2IyWWdVM0JwZEdVPSxJM05vYjNkMGIyOXNkR2x3SUZOcFoybHNJRzltSUZOd2FYUmxDaTlqWVhOMElGdEFZM1Z5YzI5eVhTQlRhV2RwYkNCdlppQlRjR2wwWlFvPSxjfDYzLHNwZWxsLDIwNzQwNyxzcGVsbCxTSElGVC0zLHw2NCxzcGVsbCwyMTIwODQsc3BlbGwsU0hJRlQtNCx8NjUjNCxTSElGVC1RLHw2NixzcGVsbCwyMDIxMzcsc3BlbGwsU0hJRlQtRSx8Njcsc3BlbGwsMjA0MTU3LHNwZWxsLFNISUZULVIsfDY4LHNwZWxsLDE4ODUwMSxzcGVsbCxTSElGVC1GLHw2OSM1LHw3MCM1LHw3MSM1LHw3MiM1LHw3MyM1LHw3NCM1LHw3NSM1LHw3NiM1LHw3NyM1LHw3OCM1LHw3OSM1LHw4MCM1LHw4MSM1LHw4MiM1LHw4MyM1LHw4NCM1LHw4NSM1LHw4NiM1LHw4NyM1LHw4OCM1LHw4OSM1LHw5MCM1LHw5MSM1LHw5MiM1LHw5MyM1LHw5NCM1LHw5NSM1LHw5NiM1LHw5NyM1LHw5OCM1LHw5OSM1LHwxMDAjNSx8MTAxIzUsfDEwMiM1LHwxMDMjNSx8MTA0IzUsfDEwNSM1LHwxMDYjNSx8MTA3IzUsfDEwOCM1LHwxMDkjNSx8MTEwIzUsfDExMSM1LHwxMTIjNSx8MTEzIzUsfDExNCM1LHwxMTUjNSx8MTE2IzUsfDExNyM1LHwxMTgjNSx8MTE5IzUsfDEyMCM1LHwxMjEsc3BlbGwsMzcyNjA4LHNwZWxsLCx8MTIyLHNwZWxsLDM3MjYxMCxzcGVsbCwsfDEyMyxzcGVsbCwzNjE1ODQsc3BlbGwsLHwxMjQjNSx8MTI1LHNwZWxsLDQwMzA5MixzcGVsbCwsfDEyNixzcGVsbCw0MjU3ODIsc3BlbGwsLHwxMjcjNSx8MTI4IzUsfDEyOSM1LHwxMzAjNSx8MTMxIzUsfDEzMiM1LHwxMzMjNSx8MTM0IzUsfDEzNSM1LHwxMzYjNSx8MTM3IzUsfDEzOCM1LHwxMzkjNSx8MTQwIzUsfDE0MSM1LHwxNDIjNSx8MTQzIzUsfDE0NCM1LHwxNDUsbWFjcm8sMTIzMTQxMSwxMjMxNDExLCwsUlc1b1lXNWpaVkZ2VEVobFlXeDBhRTFoWTNKdixJM05vYjNkMGIyOXNkR2x3Q2k5allYTjBJRnR1YjJOdmJXSmhkRjBnVW1WamRYQmxjbUYwWlFvdlkyRnpkSE5sY1hWbGJtTmxJRnRqYjIxaVlYUmRJSEpsYzJWMFBXTnZiV0poZENCcGRHVnRPakkwTkRnek9BPT0sYXwxNDYjNSx8MTQ3LGl0ZW0sMjEyMjY0LCwsfDE0OCM1LHwxNDksbWFjcm8sMTQ4LGl0ZW0sLCxWSEpwYm10bGRDQXgsSTNOb2IzZDBiMjlzZEdsd0NpOTFjMlVnVzBCamRYSnpiM0pkTVRNSyxhfDE1MCxzcGVsbCw1ODk4NCxzcGVsbCwsfDE1MSM1LHwxNTIjNSx8MTUzIzUsfDE1NCM1LHwxNTUjNSx8MTU2IzUsfDE1NyM1LHwxNTgjNSx8MTU5IzUsfDE2MCM1LHwxNjEjNSx8MTYyIzUsfDE2MyM1LHwxNjQjNSx8MTY1IzUsfDE2NiM1LHwxNjcjNSx8MTY4IzUsfDE2OSM1LHwxNzAjNSx8MTcxIzUsfDE3MiM1LHwxNzMjNSx8MTc0IzUsfDE3NSM1LHwxNzYjNSx8MTc3IzUsfDE3OCM1LHwxNzkjNSx8MTgwIzUsfDE4MSM0LDUsfDE4MiM0LGAsfDE4MyM0LEYxLHwxODQjNCxGMix8MTg1IzQsRjMsfDE4NiM0LEY0LHwxODcjNCxGNSx8MTg4IzQsRjYsfDE4OSM1LHwxOTAjNSx8MTkxIzUsfDE5MiM1LA==
A8: Balance | B8: MSxzcGVsbCwyNDg1OCxzcGVsbCwxLHwyIzQsMix8MyM0LDMsfDQjNCw0LHw1LHNwZWxsLDc3NCxzcGVsbCxRLHw2LHNwZWxsLDg5MzYsc3BlbGwsRSx8NyxzcGVsbCw0ODQzOCxzcGVsbCxSLHw4LHNwZWxsLDEyNjE4Njcsc3BlbGwsRix8OSM1LHwxMCM1LHwxMSM1LHwxMiM1LHwxMyM1LHwxNCM1LHwxNSM1LHwxNiM1LHwxNyM1LHwxOCM1LHwxOSM1LHwyMCM1LHwyMSM1LHwyMiM1LHwyMyM1LHwyNCM1LHwyNSM0LFNISUZULVosfDI2IzQsU0hJRlQtWCx8Mjcsc3BlbGwsMTMyNDY5LHNwZWxsLFNISUZULUMsfDI4IzQsU0hJRlQtVix8Mjksc3BlbGwsMjI4MTIsc3BlbGwsWix8MzAsc3BlbGwsMTg1MCxzcGVsbCxYLHwzMSxzcGVsbCw1MjExLHNwZWxsLEMsfDMyLHNwZWxsLDc4Njc1LHNwZWxsLFYsfDMzIzUsfDM0IzUsfDM1IzUsfDM2IzUsfDM3LHNwZWxsLDIwOTc0OSxzcGVsbCxBTFQtWixDVFJMLUJVVFRPTjV8MzgjNCxBTFQtWCxDVFJMLUJVVFRPTjR8MzkjNCxBTFQtQyxBTFQtQlVUVE9ONXw0MCxzcGVsbCw0NzQ3NTAsc3BlbGwsQUxULVYsQUxULUJVVFRPTjR8NDEsc3BlbGwsMTEyNixzcGVsbCxDVFJMLVosU0hJRlQtQlVUVE9ONXw0MixzcGVsbCw1MDc2OSxzcGVsbCxDVFJMLVgsU0hJRlQtQlVUVE9ONHw0MyxzcGVsbCwxMDIzODMsc3BlbGwsQ1RSTC1DLEJVVFRPTjV8NDQsc3BlbGwsNTIxNSxzcGVsbCxCVVRUT040LENUUkwtVnw0NSM1LHw0NiM1LHw0NyM1LHw0OCM1LHw0OSxzcGVsbCw4OTM2LHNwZWxsLENUUkwtMSx8NTAsc3BlbGwsNDg0Mzgsc3BlbGwsQ1RSTC0yLHw1MSxzcGVsbCwyOTE2NixzcGVsbCxDVFJMLTMsfDUyLHNwZWxsLDEyNjE4Njcsc3BlbGwsQ1RSTC00LHw1MyxzcGVsbCwyOTA4LHNwZWxsLENUUkwtUSx8NTQsc3BlbGwsMjc4MixzcGVsbCxDVFJMLUUsfDU1LHNwZWxsLDE2NDg2MixzcGVsbCxDVFJMLVIsfDU2LHNwZWxsLDIwNDg0LHNwZWxsLENUUkwtRix8NTcjNSx8NTgjNSx8NTkjNSx8NjAjNSx8NjEsc3BlbGwsMTk0MjIzLHNwZWxsLFNISUZULTEsfDYyLHNwZWxsLDM5MTUyOCxzcGVsbCxTSElGVC0yLHw2MyxzcGVsbCwyMDU2MzYsc3BlbGwsU0hJRlQtMyx8NjQsc3BlbGwsODg3NDcsc3BlbGwsU0hJRlQtNCx8NjUsc3BlbGwsMTA2ODk4LHNwZWxsLFNISUZULVEsfDY2LHNwZWxsLDEwMjM1OSxzcGVsbCxTSElGVC1FLHw2NyxzcGVsbCwzMzksc3BlbGwsU0hJRlQtUix8Njgsc3BlbGwsMjYzNyxzcGVsbCxTSElGVC1GLHw2OSM1LHw3MCM1LHw3MSM1LHw3MiM1LHw3MyxzcGVsbCw1MjIxLHNwZWxsLCx8NzQsc3BlbGwsMTgyMixzcGVsbCwsfDc1LHNwZWxsLDEwNzksc3BlbGwsLHw3NixzcGVsbCwyMjU2OCxzcGVsbCwsfDc3IzUsfDc4LHNwZWxsLDIxMzc2NCxzcGVsbCwsfDc5IzUsfDgwLHNwZWxsLDIyNTcwLHNwZWxsLCx8ODEjNSx8ODIjNSx8ODMjNSx8ODQjNSx8ODUjNSx8ODYjNSx8ODcsc3BlbGwsODkzNixzcGVsbCwsfDg4IzUsfDg5IzUsfDkwIzUsfDkxLHNwZWxsLDIwNDg0LHNwZWxsLCx8OTIjNSx8OTMjNSx8OTQsc3BlbGwsMTg1MCxzcGVsbCwsfDk1IzUsfDk2IzUsfDk3LHNwZWxsLDMzOTE3LHNwZWxsLCx8OTgsc3BlbGwsNzc3NTgsc3BlbGwsLHw5OSM1LHwxMDAsc3BlbGwsMjI4NDIsc3BlbGwsLHwxMDEsc3BlbGwsMTkyMDgxLHNwZWxsLCx8MTAyIzUsfDEwMyxzcGVsbCwyMTM3NjQsc3BlbGwsLHwxMDQsc3BlbGwsNjc5NSxzcGVsbCwsfDEwNSM1LHwxMDYjNSx8MTA3IzUsfDEwOCM1LHwxMDksc3BlbGwsMTkwOTg0LHNwZWxsLCx8MTEwLHNwZWxsLDE5NDE1MyxzcGVsbCwsfDExMSxzcGVsbCw4OTIxLHNwZWxsLCx8MTEyLHNwZWxsLDkzNDAyLHNwZWxsLCx8MTEzLHNwZWxsLDc4Njc0LHNwZWxsLCx8MTE0LHNwZWxsLDE5MTAzNCxzcGVsbCwsfDExNSxzcGVsbCwxMjMzMzQ2LHNwZWxsLCx8MTE2LHNwZWxsLDIwMjc3MCxzcGVsbCwsfDExNyM1LHwxMTgjNSx8MTE5IzUsfDEyMCM1LHwxMjEjNSx8MTIyIzUsfDEyMyM1LHwxMjQjNSx8MTI1IzUsfDEyNiM1LHwxMjcjNSx8MTI4IzUsfDEyOSM1LHwxMzAjNSx8MTMxIzUsfDEzMiM1LHwxMzMjNSx8MTM0IzUsfDEzNSM1LHwxMzYjNSx8MTM3IzUsfDEzOCM1LHwxMzkjNSx8MTQwIzUsfDE0MSM1LHwxNDIjNSx8MTQzIzUsfDE0NCM1LHwxNDUsbWFjcm8sMTIzMTQxMSwxMjMxNDExLCwsUlc1b1lXNWpaVkZ2VEVobFlXeDBhRTFoWTNKdixJM05vYjNkMGIyOXNkR2x3Q2k5allYTjBJRnR1YjJOdmJXSmhkRjBnVW1WamRYQmxjbUYwWlFvdlkyRnpkSE5sY1hWbGJtTmxJRnRqYjIxaVlYUmRJSEpsYzJWMFBXTnZiV0poZENCcGRHVnRPakkwTkRnek9BPT0sYXwxNDYsbWFjcm8sMTQ1LGl0ZW0sLCxSVzVvWVc1alpWRnZURVJ5YVc1clRXRmpjbTg9LEkzTm9iM2QwYjI5c2RHbHdDaTlqWVhOMGMyVnhkV1Z1WTJVZ2NtVnpaWFE5WTI5dFltRjBJR2wwWlcwNk1UY3lNRFl6LGF8MTQ3LG1hY3JvLDE0NixpdGVtLCwsUkdGdFlXZGxJRkJ2ZEE9PSxJM05vYjNkMGIyOXNkR2x3Q2k5MWMyVWdhWFJsYlRveU5ERXpNRGdLLGF8MTQ4LG1hY3JvLDExIzQsVUd4aFkyVm9iMnhrWlhJPSxVR3hoWTJWb2IyeGtaWElnYldGamNtOGdabTl5SUdsMFpXMXpJR3hwYTJVZ2JtbDBjbThnWW05dmMzUWdiM0lnYzJ4dmR5Qm1ZV3hzSUdOc2IyRnJMZ289LGF8MTQ5LG1hY3JvLDE0IzQsVkhKcGJtdGxkQ0F4LEkzTm9iM2QwYjI5c2RHbHdDaTkxYzJVZ1cwQmpkWEp6YjNKZE1UTUssYXwxNTAsc3BlbGwsNTg5ODQsc3BlbGwsLHwxNTEjNSx8MTUyIzUsfDE1MyM1LHwxNTQjNSx8MTU1IzUsfDE1NiM1LHwxNTcjNSx8MTU4IzUsfDE1OSM1LHwxNjAjNSx8MTYxIzUsfDE2MiM1LHwxNjMjNSx8MTY0IzUsfDE2NSM1LHwxNjYjNSx8MTY3IzUsfDE2OCM1LHwxNjkjNSx8MTcwIzUsfDE3MSM1LHwxNzIjNSx8MTczIzUsfDE3NCM1LHwxNzUjNSx8MTc2IzUsfDE3NyM1LHwxNzgjNSx8MTc5IzUsfDE4MCM1LA== | C8: MCxfaGVhZGVyLGRydWlkLDEwMiwsfDEsc3BlbGwsMjQ4NTgsc3BlbGwsMSx8MiM0LDIsfDMjNCwzLHw0IzQsNCx8NSxzcGVsbCw3NzQsc3BlbGwsUSx8NixzcGVsbCw4OTM2LHNwZWxsLEUsfDcsc3BlbGwsNDg0Mzgsc3BlbGwsUix8OCxzcGVsbCwxMjYxODY3LHNwZWxsLEYsfDkjNSx8MTAjNSx8MTEjNSx8MTIjNSx8MTMjNSx8MTQjNSx8MTUjNSx8MTYjNSx8MTcjNSx8MTgjNSx8MTkjNSx8MjAjNSx8MjEjNSx8MjIjNSx8MjMjNSx8MjQjNSx8MjUjNCxTSElGVC1aLHwyNiM0LFNISUZULVgsfDI3LHNwZWxsLDEzMjQ2OSxzcGVsbCxTSElGVC1DLHwyOCM0LFNISUZULVYsfDI5LHNwZWxsLDIyODEyLHNwZWxsLFosfDMwLHNwZWxsLDE4NTAsc3BlbGwsWCx8MzEsc3BlbGwsNTIxMSxzcGVsbCxDLHwzMixzcGVsbCw3ODY3NSxzcGVsbCxWLHwzMyM1LHwzNCM1LHwzNSM1LHwzNiM1LHwzNyxzcGVsbCwyMDk3NDksc3BlbGwsQUxULVosQ1RSTC1CVVRUT041fDM4IzQsQUxULVgsQ1RSTC1CVVRUT040fDM5LHNwZWxsLDQ3NDc1MCxzcGVsbCxBTFQtQyxBTFQtQlVUVE9ONXw0MCxzcGVsbCw3ODMsc3BlbGwsQUxULVYsQUxULUJVVFRPTjR8NDEsc3BlbGwsMTEyNixzcGVsbCxDVFJMLVosU0hJRlQtQlVUVE9ONXw0MixzcGVsbCw1MDc2OSxzcGVsbCxDVFJMLVgsU0hJRlQtQlVUVE9ONHw0MyxzcGVsbCwxMDIzODMsc3BlbGwsQ1RSTC1DLEJVVFRPTjV8NDQsc3BlbGwsNTIxNSxzcGVsbCxCVVRUT040LENUUkwtVnw0NSM1LHw0NiM1LHw0NyM1LHw0OCM1LHw0OSxzcGVsbCw4OTM2LHNwZWxsLENUUkwtMSx8NTAsc3BlbGwsNDg0Mzgsc3BlbGwsQ1RSTC0yLHw1MSxzcGVsbCwyOTE2NixzcGVsbCxDVFJMLTMsfDUyLHNwZWxsLDEyNjE4Njcsc3BlbGwsQ1RSTC00LHw1MyxzcGVsbCwyOTA4LHNwZWxsLENUUkwtUSx8NTQsc3BlbGwsMjc4MixzcGVsbCxDVFJMLUUsfDU1LHNwZWxsLDE2NDg2MixzcGVsbCxDVFJMLVIsfDU2LHNwZWxsLDIwNDg0LHNwZWxsLENUUkwtRix8NTcjNSx8NTgjNSx8NTkjNSx8NjAjNSx8NjEsc3BlbGwsMTk0MjIzLHNwZWxsLFNISUZULTEsfDYyLHNwZWxsLDM5MTUyOCxzcGVsbCxTSElGVC0yLHw2MyxzcGVsbCwyMDU2MzYsc3BlbGwsU0hJRlQtMyx8NjQsc3BlbGwsODg3NDcsc3BlbGwsU0hJRlQtNCx8NjUsc3BlbGwsMTA2ODk4LHNwZWxsLFNISUZULVEsfDY2LHNwZWxsLDEwMjM1OSxzcGVsbCxTSElGVC1FLHw2NyxzcGVsbCwzMzksc3BlbGwsU0hJRlQtUix8Njgsc3BlbGwsMjYzNyxzcGVsbCxTSElGVC1GLHw2OSM1LHw3MCM1LHw3MSM1LHw3MiM1LHw3MyxzcGVsbCw1MjIxLHNwZWxsLCx8NzQsc3BlbGwsMTgyMixzcGVsbCwsfDc1LHNwZWxsLDEwNzksc3BlbGwsLHw3NixzcGVsbCwyMjU2OCxzcGVsbCwsfDc3IzUsfDc4LHNwZWxsLDIxMzc2NCxzcGVsbCwsfDc5IzUsfDgwLHNwZWxsLDIyNTcwLHNwZWxsLCx8ODEjNSx8ODIjNSx8ODMjNSx8ODQjNSx8ODUjNSx8ODYjNSx8ODcsc3BlbGwsODkzNixzcGVsbCwsfDg4IzUsfDg5IzUsfDkwIzUsfDkxLHNwZWxsLDIwNDg0LHNwZWxsLCx8OTIjNSx8OTMjNSx8OTQsc3BlbGwsMTg1MCxzcGVsbCwsfDk1IzUsfDk2IzUsfDk3LHNwZWxsLDMzOTE3LHNwZWxsLCx8OTgsc3BlbGwsNzc3NTgsc3BlbGwsLHw5OSM1LHwxMDAsc3BlbGwsMjI4NDIsc3BlbGwsLHwxMDEsc3BlbGwsMTkyMDgxLHNwZWxsLCx8MTAyIzUsfDEwMyxzcGVsbCwyMTM3NjQsc3BlbGwsLHwxMDQsc3BlbGwsNjc5NSxzcGVsbCwsfDEwNSM1LHwxMDYjNSx8MTA3IzUsfDEwOCM1LHwxMDksc3BlbGwsMTkwOTg0LHNwZWxsLCx8MTEwLHNwZWxsLDE5NDE1MyxzcGVsbCwsfDExMSxzcGVsbCw4OTIxLHNwZWxsLCx8MTEyLHNwZWxsLDkzNDAyLHNwZWxsLCx8MTEzLHNwZWxsLDc4Njc0LHNwZWxsLCx8MTE0LHNwZWxsLDE5MTAzNCxzcGVsbCwsfDExNSxzcGVsbCwxMjMzMzQ2LHNwZWxsLCx8MTE2LHNwZWxsLDIwMjc3MCxzcGVsbCwsfDExNyM1LHwxMTgjNSx8MTE5IzUsfDEyMCM1LHwxMjEjNSx8MTIyIzUsfDEyMyM1LHwxMjQjNSx8MTI1IzUsfDEyNiM1LHwxMjcjNSx8MTI4IzUsfDEyOSM1LHwxMzAjNSx8MTMxIzUsfDEzMiM1LHwxMzMjNSx8MTM0IzUsfDEzNSM1LHwxMzYjNSx8MTM3IzUsfDEzOCM1LHwxMzkjNSx8MTQwIzUsfDE0MSM1LHwxNDIjNSx8MTQzIzUsfDE0NCM1LHwxNDUsbWFjcm8sMTIzMTQxMSwxMjMxNDExLCwsUlc1b1lXNWpaVkZ2VEVobFlXeDBhRTFoWTNKdixJM05vYjNkMGIyOXNkR2x3Q2k5allYTjBJRnR1YjJOdmJXSmhkRjBnVW1WamRYQmxjbUYwWlFvdlkyRnpkSE5sY1hWbGJtTmxJRnRqYjIxaVlYUmRJSEpsYzJWMFBXTnZiV0poZENCcGRHVnRPakkwTkRnek9BPT0sYXwxNDYsbWFjcm8sMTQ1LGl0ZW0sLCxSVzVvWVc1alpWRnZURVJ5YVc1clRXRmpjbTg9LEkzTm9iM2QwYjI5c2RHbHdDaTlqWVhOMGMyVnhkV1Z1WTJVZ2NtVnpaWFE5WTI5dFltRjBJR2wwWlcwNk1UY3lNRFl6LGF8MTQ3LG1hY3JvLDE0NixpdGVtLCwsUkdGdFlXZGxJRkJ2ZEE9PSxJM05vYjNkMGIyOXNkR2x3Q2k5MWMyVWdhWFJsYlRveU5ERXpNRGdLLGF8MTQ4LG1hY3JvLDExIzQsVUd4aFkyVm9iMnhrWlhJPSxVR3hoWTJWb2IyeGtaWElnYldGamNtOGdabTl5SUdsMFpXMXpJR3hwYTJVZ2JtbDBjbThnWW05dmMzUWdiM0lnYzJ4dmR5Qm1ZV3hzSUdOc2IyRnJMZ289LGF8MTQ5LG1hY3JvLDE0IzQsVkhKcGJtdGxkQ0F4LEkzTm9iM2QwYjI5c2RHbHdDaTkxYzJVZ1cwQmpkWEp6YjNKZE1UTUssYXwxNTAsc3BlbGwsNTg5ODQsc3BlbGwsLHwxNTEjNSx8MTUyIzUsfDE1MyM1LHwxNTQjNSx8MTU1IzUsfDE1NiM1LHwxNTcjNSx8MTU4IzUsfDE1OSM1LHwxNjAjNSx8MTYxIzUsfDE2MiM1LHwxNjMjNSx8MTY0IzUsfDE2NSM1LHwxNjYjNSx8MTY3IzUsfDE2OCM1LHwxNjkjNSx8MTcwIzUsfDE3MSM1LHwxNzIjNSx8MTczIzUsfDE3NCM1LHwxNzUjNSx8MTc2IzUsfDE3NyM1LHwxNzgjNSx8MTc5IzUsfDE4MCM1LHwxODEjNCw1LHwxODIjNCxgLHwxODMjNCxGMSx8MTg0IzQsRjIsfDE4NSM0LEYzLHwxODYjNCxGNCx8MTg3IzQsRjUsfDE4OCM0LEY2LHwxODkjNSx8MTkwIzUsfDE5MSM1LHwxOTIjNSw=
